Workbook

Sheet Products
A1: Code | B1: Description
A2: ART01505 | B2: BAHIA PET 5L
A3: ART01504 | B3: WOW Bonbons Bocal 100 PCS - Choco Banane
A4: ART01503 | B4: WOW Barre Biscuit Cannelle Pack 24 PCS
A5: ART01507 | B5: CHUPITA Sucette Coconut 100PCS
A6: ART01508 | B6: OLA CREME Sucette Fraise 100PCS
A7: ART01506 | B7: CHUPITA Sucette Raisin 100PCS
A8: ART01509 | B8: ROSTOY Jus Peche Et Mangue 1L Carton
A9: ART01510 | B9: ROSTOY Jus Mix de Fruits 1L Carton
A10: ART01512 | B10: YAOURT FRUITS MIX BAUER 100G
A11: ART01513 | B11: YAOURT FRUITS MIX BAUER 500G
A12: ART01514 | B12: TAOUS Lavande Pack 4 Savons 125G
... A4204: ART03874 | B4204: SEÑOR MAYOR LIQUIDE VAISSELLE 750ML CITRON VERT CONCENTRÉ

Sheet Feuil1
A1: Family
A2: Dalaa VP / Baqqal / RP
A3: Calin RP
A4: Mio main (1k+500gr)
A5: Mia
A6: Calin VP
A7: Nova
A8: Prima
A9: Mio Liquid Vaisselle
A10: Mio Javel
A11: Douceur
A12: Mio Matic
... A25: Fromy

Sheet Famille-Produit
A1: Code | B1: Description | C1: Famille | E1: Famille | F1: Nb Produits
A2: =Products!A930 -> CF35250 | B2: =Products!B930 -> TOBIGO CROUSTY TIRAMISSU CRN 30UN | C2: =IF(OR(ISNUMBER(SEARCH("SELHAM",B2)),ISNUMBER(SEARCH("LHAFLA",B2)),ISNUMBER(SEARCH("ZINE",B2)),ISNUMBER(SEARCH("tiyay",B2)),ISNUMBER(SEARCH("alouns",B2)),ISNUMBER(SEARCH("lmhrat",B2))),"The Al Itkane",IF(AND(ISNUMBER(SEARCH("CALIN",B2)),ISNUMBER(SEARCH("RP",B2)),NOT(ISNUMBER(SEARCH("VP",B2)))),"Calin RP",IF(AND(ISNUMBER(SEARCH("CALIN",B2)),ISNUMBER(SEARCH("VP",B2))),"Calin VP",IF(AND(ISNUMBER(SEARCH("MIO",B2)),OR(ISNUMBER(SEARCH("Vaisselle",B2)),ISNUMBER(SEARCH("vaisselle",B2)))),"Mio Liquid Vaisselle",IF(AND(ISNUMBER(SEARCH("MIO",B2)),ISNUMBER(SEARCH("Javel",B2))),"Mio Javel",IF(AND(ISNUMBER(SEARCH("MIO",B2)),ISNUMBER(SEARCH("Matic",B2))),"Mio Matic",IF(AND(ISNUMBER(SEARCH("MIO",B2)),OR(ISNUMBER(SEARCH("Détérgent",B2)),ISNUMBER(SEARCH("Poudre",B2)),ISNUMBER(SEARCH("Semi Auto",B2)),ISNUMBER(SEARCH("1KG",B2)),ISNUMBER(SEARCH("500G",B2)),ISNUMBER(SEARCH("10KG",B2)),ISNUMBER(SEARCH("1.5K",B2)),ISNUMBER(SEARCH("215G",B2)),ISNUMBER(SEARCH("350G",B2)),ISNUMBER(SEARCH("90G",B2)),ISNUMBER(SEARCH("Gold",B2)),ISNUMBER(SEARCH("Citron",B2)),ISNUMBER(SEARCH("Rose",B2)),ISNUMBER(SEARCH("Lessive",B2))),NOT(OR(ISNUMBER(SEARCH("Vaisselle",B2)),ISNUMBER(SEARCH("Javel",B2)),ISNUMBER(SEARCH("Matic",B2)),ISNUMBER(SEARCH("Nettoyant",B2)),ISNUMBER(SEARCH("Pâte",B2)),ISNUMBER(SEARCH("Lave",B2)),ISNUMBER(SEARCH("Détartrant",B2))))),"Mio main (1k+500gr)",IF(AND(ISNUMBER(SEARCH("PAPILLON",B2)),OR(ISNUMBER(SEARCH("Papier",B2)),ISNUMBER(SEARCH("Hygiénique",B2)),ISNUMBER(SEARCH("HYGIÉNIQUE",B2))),NOT(OR(ISNUMBER(SEARCH("Lingette",B2)),ISNUMBER(SEARCH("Mouchoir",B2))))),"Papillon Papier",IF(OR(ISNUMBER(SEARCH("TAJ AL SAHAR",B2)),ISNUMBER(SEARCH("TAJ BLADI",B2)),ISNUMBER(SEARCH("TAJ BELADI",B2)),ISNUMBER(SEARCH("Tilal Assahra",B2)),ISNUMBER(SEARCH("Jawharat Asahra",B2))),"TAJ SAHARA",IF(AND(OR(ISNUMBER(SEARCH("AL ITKANE",B2)),ISNUMBER(SEARCH("ALITKANE",B2)),ISNUMBER(SEARCH("PRESTO",B2))),NOT(OR(ISNUMBER(SEARCH("Thé",B2)),ISNUMBER(SEARCH("THE ",B2)),ISNUMBER(SEARCH("thé",B2)),ISNUMBER(SEARCH("SELHAM",B2)),ISNUMBER(SEARCH("LHAFLA",B2)),ISNUMBER(SEARCH("ZINE",B2)),ISNUMBER(SEARCH("tiyay",B2)),ISNUMBER(SEARCH("alouns",B2)),ISNUMBER(SEARCH("lmhrat",B2))))),"Al Itkrans + Presto",IF(OR(ISNUMBER(SEARCH("DALAA",B2)),ISNUMBER(SEARCH("CS-DALAA",B2)),ISNUMBER(SEARCH("DALINA",B2))),"Dalaa VP / Baqqal / RP",IF(OR(LEFT(UPPER(B2),4)="MIA ",LEFT(UPPER(B2),6)="CS-MIA"),"Mia",IF(OR(LEFT(UPPER(B2),5)="NOVA ",LEFT(UPPER(B2),7)="CS-NOVA"),"Nova",IF(OR(ISNUMBER(SEARCH("PRIMA ",B2)),ISNUMBER(SEARCH("CS-PRIMA",B2))),"Prima",IF(OR(ISNUMBER(SEARCH("Douceur",B2)),ISNUMBER(SEARCH("DOUCEUR",B2))),"Douceur",IF(OR(ISNUMBER(SEARCH("SANGO",B2)),ISNUMBER(SEARCH("CS-SANGO",B2))),"SANGO",IF(ISNUMBER(SEARCH("BLANDOUX",B2)),"Blandoux",IF(ISNUMBER(SEARCH("SHIWAMI",B2)),"Shiwame",IF(ISNUMBER(SEARCH("KELLOGG",B2)),"Kelloggs",IF(OR(ISNUMBER(SEARCH("TOBIGO",B2)),ISNUMBER(SEARCH("DWIST",B2))),"Tobigo",IF(OR(ISNUMBER(SEARCH("MARISOL",B2)),ISNUMBER(SEARCH("MARESOL",B2))),"Maresol",IF(OR(ISNUMBER(SEARCH("TAKIS",B2)),ISNUMBER(SEARCH("TAKYS",B2))),"TAKYS",IF(ISNUMBER(SEARCH("TAWIL",B2)),"Tawil",IF(ISNUMBER(SEARCH("FROMY",B2)),"Fromy","")))))))))))))))))))))))) -> Tobigo | E2: Dalaa VP / Baqqal / RP | F2: =COUNTIF(C:C,E2) -> 65
A3: =Products!A940 -> ART00968 | B3: =Products!B940 -> TOBIGO Roundy Cacao Biscuit Crème Vanille | C3: =IF(OR(ISNUMBER(SEARCH("SELHAM",B3)),ISNUMBER(SEARCH("LHAFLA",B3)),ISNUMBER(SEARCH("ZINE",B3)),ISNUMBER(SEARCH("tiyay",B3)),ISNUMBER(SEARCH("alouns",B3)),ISNUMBER(SEARCH("lmhrat",B3))),"The Al Itkane",IF(AND(ISNUMBER(SEARCH("CALIN",B3)),ISNUMBER(SEARCH("RP",B3)),NOT(ISNUMBER(SEARCH("VP",B3)))),"Calin RP",IF(AND(ISNUMBER(SEARCH("CALIN",B3)),ISNUMBER(SEARCH("VP",B3))),"Calin VP",IF(AND(ISNUMBER(SEARCH("MIO",B3)),OR(ISNUMBER(SEARCH("Vaisselle",B3)),ISNUMBER(SEARCH("vaisselle",B3)))),"Mio Liquid Vaisselle",IF(AND(ISNUMBER(SEARCH("MIO",B3)),ISNUMBER(SEARCH("Javel",B3))),"Mio Javel",IF(AND(ISNUMBER(SEARCH("MIO",B3)),ISNUMBER(SEARCH("Matic",B3))),"Mio Matic",IF(AND(ISNUMBER(SEARCH("MIO",B3)),OR(ISNUMBER(SEARCH("Détérgent",B3)),ISNUMBER(SEARCH("Poudre",B3)),ISNUMBER(SEARCH("Semi Auto",B3)),ISNUMBER(SEARCH("1KG",B3)),ISNUMBER(SEARCH("500G",B3)),ISNUMBER(SEARCH("10KG",B3)),ISNUMBER(SEARCH("1.5K",B3)),ISNUMBER(SEARCH("215G",B3)),ISNUMBER(SEARCH("350G",B3)),ISNUMBER(SEARCH("90G",B3)),ISNUMBER(SEARCH("Gold",B3)),ISNUMBER(SEARCH("Citron",B3)),ISNUMBER(SEARCH("Rose",B3)),ISNUMBER(SEARCH("Lessive",B3))),NOT(OR(ISNUMBER(SEARCH("Vaisselle",B3)),ISNUMBER(SEARCH("Javel",B3)),ISNUMBER(SEARCH("Matic",B3)),ISNUMBER(SEARCH("Nettoyant",B3)),ISNUMBER(SEARCH("Pâte",B3)),ISNUMBER(SEARCH("Lave",B3)),ISNUMBER(SEARCH("Détartrant",B3))))),"Mio main (1k+500gr)",IF(AND(ISNUMBER(SEARCH("PAPILLON",B3)),OR(ISNUMBER(SEARCH("Papier",B3)),ISNUMBER(SEARCH("Hygiénique",B3)),ISNUMBER(SEARCH("HYGIÉNIQUE",B3))),NOT(OR(ISNUMBER(SEARCH("Lingette",B3)),ISNUMBER(SEARCH("Mouchoir",B3))))),"Papillon Papier",IF(OR(ISNUMBER(SEARCH("TAJ AL SAHAR",B3)),ISNUMBER(SEARCH("TAJ BLADI",B3)),ISNUMBER(SEARCH("TAJ BELADI",B3)),ISNUMBER(SEARCH("Tilal Assahra",B3)),ISNUMBER(SEARCH("Jawharat Asahra",B3))),"TAJ SAHARA",IF(AND(OR(ISNUMBER(SEARCH("AL ITKANE",B3)),ISNUMBER(SEARCH("ALITKANE",B3)),ISNUMBER(SEARCH("PRESTO",B3))),NOT(OR(ISNUMBER(SEARCH("Thé",B3)),ISNUMBER(SEARCH("THE ",B3)),ISNUMBER(SEARCH("thé",B3)),ISNUMBER(SEARCH("SELHAM",B3)),ISNUMBER(SEARCH("LHAFLA",B3)),ISNUMBER(SEARCH("ZINE",B3)),ISNUMBER(SEARCH("tiyay",B3)),ISNUMBER(SEARCH("alouns",B3)),ISNUMBER(SEARCH("lmhrat",B3))))),"Al Itkrans + Presto",IF(OR(ISNUMBER(SEARCH("DALAA",B3)),ISNUMBER(SEARCH("CS-DALAA",B3)),ISNUMBER(SEARCH("DALINA",B3))),"Dalaa VP / Baqqal / RP",IF(OR(LEFT(UPPER(B3),4)="MIA ",LEFT(UPPER(B3),6)="CS-MIA"),"Mia",IF(OR(LEFT(UPPER(B3),5)="NOVA ",LEFT(UPPER(B3),7)="CS-NOVA"),"Nova",IF(OR(ISNUMBER(SEARCH("PRIMA ",B3)),ISNUMBER(SEARCH("CS-PRIMA",B3))),"Prima",IF(OR(ISNUMBER(SEARCH("Douceur",B3)),ISNUMBER(SEARCH("DOUCEUR",B3))),"Douceur",IF(OR(ISNUMBER(SEARCH("SANGO",B3)),ISNUMBER(SEARCH("CS-SANGO",B3))),"SANGO",IF(ISNUMBER(SEARCH("BLANDOUX",B3)),"Blandoux",IF(ISNUMBER(SEARCH("SHIWAMI",B3)),"Shiwame",IF(ISNUMBER(SEARCH("KELLOGG",B3)),"Kelloggs",IF(OR(ISNUMBER(SEARCH("TOBIGO",B3)),ISNUMBER(SEARCH("DWIST",B3))),"Tobigo",IF(OR(ISNUMBER(SEARCH("MARISOL",B3)),ISNUMBER(SEARCH("MARESOL",B3))),"Maresol",IF(OR(ISNUMBER(SEARCH("TAKIS",B3)),ISNUMBER(SEARCH("TAKYS",B3))),"TAKYS",IF(ISNUMBER(SEARCH("TAWIL",B3)),"Tawil",IF(ISNUMBER(SEARCH("FROMY",B3)),"Fromy","")))))))))))))))))))))))) -> Tobigo | E3: Calin RP | F3: =COUNTIF(C:C,E3) -> 15
A4: =Products!A1125 -> CF35266 | B4: =Products!B1125 -> TOBIGO DONITO CARAMEL CRN 30UN | C4: =IF(OR(ISNUMBER(SEARCH("SELHAM",B4)),ISNUMBER(SEARCH("LHAFLA",B4)),ISNUMBER(SEARCH("ZINE",B4)),ISNUMBER(SEARCH("tiyay",B4)),ISNUMBER(SEARCH("alouns",B4)),ISNUMBER(SEARCH("lmhrat",B4))),"The Al Itkane",IF(AND(ISNUMBER(SEARCH("CALIN",B4)),ISNUMBER(SEARCH("RP",B4)),NOT(ISNUMBER(SEARCH("VP",B4)))),"Calin RP",IF(AND(ISNUMBER(SEARCH("CALIN",B4)),ISNUMBER(SEARCH("VP",B4))),"Calin VP",IF(AND(ISNUMBER(SEARCH("MIO",B4)),OR(ISNUMBER(SEARCH("Vaisselle",B4)),ISNUMBER(SEARCH("vaisselle",B4)))),"Mio Liquid Vaisselle",IF(AND(ISNUMBER(SEARCH("MIO",B4)),ISNUMBER(SEARCH("Javel",B4))),"Mio Javel",IF(AND(ISNUMBER(SEARCH("MIO",B4)),ISNUMBER(SEARCH("Matic",B4))),"Mio Matic",IF(AND(ISNUMBER(SEARCH("MIO",B4)),OR(ISNUMBER(SEARCH("Détérgent",B4)),ISNUMBER(SEARCH("Poudre",B4)),ISNUMBER(SEARCH("Semi Auto",B4)),ISNUMBER(SEARCH("1KG",B4)),ISNUMBER(SEARCH("500G",B4)),ISNUMBER(SEARCH("10KG",B4)),ISNUMBER(SEARCH("1.5K",B4)),ISNUMBER(SEARCH("215G",B4)),ISNUMBER(SEARCH("350G",B4)),ISNUMBER(SEARCH("90G",B4)),ISNUMBER(SEARCH("Gold",B4)),ISNUMBER(SEARCH("Citron",B4)),ISNUMBER(SEARCH("Rose",B4)),ISNUMBER(SEARCH("Lessive",B4))),NOT(OR(ISNUMBER(SEARCH("Vaisselle",B4)),ISNUMBER(SEARCH("Javel",B4)),ISNUMBER(SEARCH("Matic",B4)),ISNUMBER(SEARCH("Nettoyant",B4)),ISNUMBER(SEARCH("Pâte",B4)),ISNUMBER(SEARCH("Lave",B4)),ISNUMBER(SEARCH("Détartrant",B4))))),"Mio main (1k+500gr)",IF(AND(ISNUMBER(SEARCH("PAPILLON",B4)),OR(ISNUMBER(SEARCH("Papier",B4)),ISNUMBER(SEARCH("Hygiénique",B4)),ISNUMBER(SEARCH("HYGIÉNIQUE",B4))),NOT(OR(ISNUMBER(SEARCH("Lingette",B4)),ISNUMBER(SEARCH("Mouchoir",B4))))),"Papillon Papier",IF(OR(ISNUMBER(SEARCH("TAJ AL SAHAR",B4)),ISNUMBER(SEARCH("TAJ BLADI",B4)),ISNUMBER(SEARCH("TAJ BELADI",B4)),ISNUMBER(SEARCH("Tilal Assahra",B4)),ISNUMBER(SEARCH("Jawharat Asahra",B4))),"TAJ SAHARA",IF(AND(OR(ISNUMBER(SEARCH("AL ITKANE",B4)),ISNUMBER(SEARCH("ALITKANE",B4)),ISNUMBER(SEARCH("PRESTO",B4))),NOT(OR(ISNUMBER(SEARCH("Thé",B4)),ISNUMBER(SEARCH("THE ",B4)),ISNUMBER(SEARCH("thé",B4)),ISNUMBER(SEARCH("SELHAM",B4)),ISNUMBER(SEARCH("LHAFLA",B4)),ISNUMBER(SEARCH("ZINE",B4)),ISNUMBER(SEARCH("tiyay",B4)),ISNUMBER(SEARCH("alouns",B4)),ISNUMBER(SEARCH("lmhrat",B4))))),"Al Itkrans + Presto",IF(OR(ISNUMBER(SEARCH("DALAA",B4)),ISNUMBER(SEARCH("CS-DALAA",B4)),ISNUMBER(SEARCH("DALINA",B4))),"Dalaa VP / Baqqal / RP",IF(OR(LEFT(UPPER(B4),4)="MIA ",LEFT(UPPER(B4),6)="CS-MIA"),"Mia",IF(OR(LEFT(UPPER(B4),5)="NOVA ",LEFT(UPPER(B4),7)="CS-NOVA"),"Nova",IF(OR(ISNUMBER(SEARCH("PRIMA ",B4)),ISNUMBER(SEARCH("CS-PRIMA",B4))),"Prima",IF(OR(ISNUMBER(SEARCH("Douceur",B4)),ISNUMBER(SEARCH("DOUCEUR",B4))),"Douceur",IF(OR(ISNUMBER(SEARCH("SANGO",B4)),ISNUMBER(SEARCH("CS-SANGO",B4))),"SANGO",IF(ISNUMBER(SEARCH("BLANDOUX",B4)),"Blandoux",IF(ISNUMBER(SEARCH("SHIWAMI",B4)),"Shiwame",IF(ISNUMBER(SEARCH("KELLOGG",B4)),"Kelloggs",IF(OR(ISNUMBER(SEARCH("TOBIGO",B4)),ISNUMBER(SEARCH("DWIST",B4))),"Tobigo",IF(OR(ISNUMBER(SEARCH("MARISOL",B4)),ISNUMBER(SEARCH("MARESOL",B4))),"Maresol",IF(OR(ISNUMBER(SEARCH("TAKIS",B4)),ISNUMBER(SEARCH("TAKYS",B4))),"TAKYS",IF(ISNUMBER(SEARCH("TAWIL",B4)),"Tawil",IF(ISNUMBER(SEARCH("FROMY",B4)),"Fromy","")))))))))))))))))))))))) -> Tobigo | E4: Mio main (1k+500gr) | F4: =COUNTIF(C:C,E4) -> 25
A5: =Products!A1126 -> CF35267 | B5: =Products!B1126 -> TOBIGO DONITO CHOCO CRN 30UN | C5: =IF(OR(ISNUMBER(SEARCH("SELHAM",B5)),ISNUMBER(SEARCH("LHAFLA",B5)),ISNUMBER(SEARCH("ZINE",B5)),ISNUMBER(SEARCH("tiyay",B5)),ISNUMBER(SEARCH("alouns",B5)),ISNUMBER(SEARCH("lmhrat",B5))),"The Al Itkane",IF(AND(ISNUMBER(SEARCH("CALIN",B5)),ISNUMBER(SEARCH("RP",B5)),NOT(ISNUMBER(SEARCH("VP",B5)))),"Calin RP",IF(AND(ISNUMBER(SEARCH("CALIN",B5)),ISNUMBER(SEARCH("VP",B5))),"Calin VP",IF(AND(ISNUMBER(SEARCH("MIO",B5)),OR(ISNUMBER(SEARCH("Vaisselle",B5)),ISNUMBER(SEARCH("vaisselle",B5)))),"Mio Liquid Vaisselle",IF(AND(ISNUMBER(SEARCH("MIO",B5)),ISNUMBER(SEARCH("Javel",B5))),"Mio Javel",IF(AND(ISNUMBER(SEARCH("MIO",B5)),ISNUMBER(SEARCH("Matic",B5))),"Mio Matic",IF(AND(ISNUMBER(SEARCH("MIO",B5)),OR(ISNUMBER(SEARCH("Détérgent",B5)),ISNUMBER(SEARCH("Poudre",B5)),ISNUMBER(SEARCH("Semi Auto",B5)),ISNUMBER(SEARCH("1KG",B5)),ISNUMBER(SEARCH("500G",B5)),ISNUMBER(SEARCH("10KG",B5)),ISNUMBER(SEARCH("1.5K",B5)),ISNUMBER(SEARCH("215G",B5)),ISNUMBER(SEARCH("350G",B5)),ISNUMBER(SEARCH("90G",B5)),ISNUMBER(SEARCH("Gold",B5)),ISNUMBER(SEARCH("Citron",B5)),ISNUMBER(SEARCH("Rose",B5)),ISNUMBER(SEARCH("Lessive",B5))),NOT(OR(ISNUMBER(SEARCH("Vaisselle",B5)),ISNUMBER(SEARCH("Javel",B5)),ISNUMBER(SEARCH("Matic",B5)),ISNUMBER(SEARCH("Nettoyant",B5)),ISNUMBER(SEARCH("Pâte",B5)),ISNUMBER(SEARCH("Lave",B5)),ISNUMBER(SEARCH("Détartrant",B5))))),"Mio main (1k+500gr)",IF(AND(ISNUMBER(SEARCH("PAPILLON",B5)),OR(ISNUMBER(SEARCH("Papier",B5)),ISNUMBER(SEARCH("Hygiénique",B5)),ISNUMBER(SEARCH("HYGIÉNIQUE",B5))),NOT(OR(ISNUMBER(SEARCH("Lingette",B5)),ISNUMBER(SEARCH("Mouchoir",B5))))),"Papillon Papier",IF(OR(ISNUMBER(SEARCH("TAJ AL SAHAR",B5)),ISNUMBER(SEARCH("TAJ BLADI",B5)),ISNUMBER(SEARCH("TAJ BELADI",B5)),ISNUMBER(SEARCH("Tilal Assahra",B5)),ISNUMBER(SEARCH("Jawharat Asahra",B5))),"TAJ SAHARA",IF(AND(OR(ISNUMBER(SEARCH("AL ITKANE",B5)),ISNUMBER(SEARCH("ALITKANE",B5)),ISNUMBER(SEARCH("PRESTO",B5))),NOT(OR(ISNUMBER(SEARCH("Thé",B5)),ISNUMBER(SEARCH("THE ",B5)),ISNUMBER(SEARCH("thé",B5)),ISNUMBER(SEARCH("SELHAM",B5)),ISNUMBER(SEARCH("LHAFLA",B5)),ISNUMBER(SEARCH("ZINE",B5)),ISNUMBER(SEARCH("tiyay",B5)),ISNUMBER(SEARCH("alouns",B5)),ISNUMBER(SEARCH("lmhrat",B5))))),"Al Itkrans + Presto",IF(OR(ISNUMBER(SEARCH("DALAA",B5)),ISNUMBER(SEARCH("CS-DALAA",B5)),ISNUMBER(SEARCH("DALINA",B5))),"Dalaa VP / Baqqal / RP",IF(OR(LEFT(UPPER(B5),4)="MIA ",LEFT(UPPER(B5),6)="CS-MIA"),"Mia",IF(OR(LEFT(UPPER(B5),5)="NOVA ",LEFT(UPPER(B5),7)="CS-NOVA"),"Nova",IF(OR(ISNUMBER(SEARCH("PRIMA ",B5)),ISNUMBER(SEARCH("CS-PRIMA",B5))),"Prima",IF(OR(ISNUMBER(SEARCH("Douceur",B5)),ISNUMBER(SEARCH("DOUCEUR",B5))),"Douceur",IF(OR(ISNUMBER(SEARCH("SANGO",B5)),ISNUMBER(SEARCH("CS-SANGO",B5))),"SANGO",IF(ISNUMBER(SEARCH("BLANDOUX",B5)),"Blandoux",IF(ISNUMBER(SEARCH("SHIWAMI",B5)),"Shiwame",IF(ISNUMBER(SEARCH("KELLOGG",B5)),"Kelloggs",IF(OR(ISNUMBER(SEARCH("TOBIGO",B5)),ISNUMBER(SEARCH("DWIST",B5))),"Tobigo",IF(OR(ISNUMBER(SEARCH("MARISOL",B5)),ISNUMBER(SEARCH("MARESOL",B5))),"Maresol",IF(OR(ISNUMBER(SEARCH("TAKIS",B5)),ISNUMBER(SEARCH("TAKYS",B5))),"TAKYS",IF(ISNUMBER(SEARCH("TAWIL",B5)),"Tawil",IF(ISNUMBER(SEARCH("FROMY",B5)),"Fromy","")))))))))))))))))))))))) -> Tobigo | E5: Mia | F5: =COUNTIF(C:C,E5) -> 20
A6: =Products!A1173 -> CF35298 | B6: =Products!B1173 -> TOBIGO SALEO ORIGINAL 24UN | C6: =IF(OR(ISNUMBER(SEARCH("SELHAM",B6)),ISNUMBER(SEARCH("LHAFLA",B6)),ISNUMBER(SEARCH("ZINE",B6)),ISNUMBER(SEARCH("tiyay",B6)),ISNUMBER(SEARCH("alouns",B6)),ISNUMBER(SEARCH("lmhrat",B6))),"The Al Itkane",IF(AND(ISNUMBER(SEARCH("CALIN",B6)),ISNUMBER(SEARCH("RP",B6)),NOT(ISNUMBER(SEARCH("VP",B6)))),"Calin RP",IF(AND(ISNUMBER(SEARCH("CALIN",B6)),ISNUMBER(SEARCH("VP",B6))),"Calin VP",IF(AND(ISNUMBER(SEARCH("MIO",B6)),OR(ISNUMBER(SEARCH("Vaisselle",B6)),ISNUMBER(SEARCH("vaisselle",B6)))),"Mio Liquid Vaisselle",IF(AND(ISNUMBER(SEARCH("MIO",B6)),ISNUMBER(SEARCH("Javel",B6))),"Mio Javel",IF(AND(ISNUMBER(SEARCH("MIO",B6)),ISNUMBER(SEARCH("Matic",B6))),"Mio Matic",IF(AND(ISNUMBER(SEARCH("MIO",B6)),OR(ISNUMBER(SEARCH("Détérgent",B6)),ISNUMBER(SEARCH("Poudre",B6)),ISNUMBER(SEARCH("Semi Auto",B6)),ISNUMBER(SEARCH("1KG",B6)),ISNUMBER(SEARCH("500G",B6)),ISNUMBER(SEARCH("10KG",B6)),ISNUMBER(SEARCH("1.5K",B6)),ISNUMBER(SEARCH("215G",B6)),ISNUMBER(SEARCH("350G",B6)),ISNUMBER(SEARCH("90G",B6)),ISNUMBER(SEARCH("Gold",B6)),ISNUMBER(SEARCH("Citron",B6)),ISNUMBER(SEARCH("Rose",B6)),ISNUMBER(SEARCH("Lessive",B6))),NOT(OR(ISNUMBER(SEARCH("Vaisselle",B6)),ISNUMBER(SEARCH("Javel",B6)),ISNUMBER(SEARCH("Matic",B6)),ISNUMBER(SEARCH("Nettoyant",B6)),ISNUMBER(SEARCH("Pâte",B6)),ISNUMBER(SEARCH("Lave",B6)),ISNUMBER(SEARCH("Détartrant",B6))))),"Mio main (1k+500gr)",IF(AND(ISNUMBER(SEARCH("PAPILLON",B6)),OR(ISNUMBER(SEARCH("Papier",B6)),ISNUMBER(SEARCH("Hygiénique",B6)),ISNUMBER(SEARCH("HYGIÉNIQUE",B6))),NOT(OR(ISNUMBER(SEARCH("Lingette",B6)),ISNUMBER(SEARCH("Mouchoir",B6))))),"Papillon Papier",IF(OR(ISNUMBER(SEARCH("TAJ AL SAHAR",B6)),ISNUMBER(SEARCH("TAJ BLADI",B6)),ISNUMBER(SEARCH("TAJ BELADI",B6)),ISNUMBER(SEARCH("Tilal Assahra",B6)),ISNUMBER(SEARCH("Jawharat Asahra",B6))),"TAJ SAHARA",IF(AND(OR(ISNUMBER(SEARCH("AL ITKANE",B6)),ISNUMBER(SEARCH("ALITKANE",B6)),ISNUMBER(SEARCH("PRESTO",B6))),NOT(OR(ISNUMBER(SEARCH("Thé",B6)),ISNUMBER(SEARCH("THE ",B6)),ISNUMBER(SEARCH("thé",B6)),ISNUMBER(SEARCH("SELHAM",B6)),ISNUMBER(SEARCH("LHAFLA",B6)),ISNUMBER(SEARCH("ZINE",B6)),ISNUMBER(SEARCH("tiyay",B6)),ISNUMBER(SEARCH("alouns",B6)),ISNUMBER(SEARCH("lmhrat",B6))))),"Al Itkrans + Presto",IF(OR(ISNUMBER(SEARCH("DALAA",B6)),ISNUMBER(SEARCH("CS-DALAA",B6)),ISNUMBER(SEARCH("DALINA",B6))),"Dalaa VP / Baqqal / RP",IF(OR(LEFT(UPPER(B6),4)="MIA ",LEFT(UPPER(B6),6)="CS-MIA"),"Mia",IF(OR(LEFT(UPPER(B6),5)="NOVA ",LEFT(UPPER(B6),7)="CS-NOVA"),"Nova",IF(OR(ISNUMBER(SEARCH("PRIMA ",B6)),ISNUMBER(SEARCH("CS-PRIMA",B6))),"Prima",IF(OR(ISNUMBER(SEARCH("Douceur",B6)),ISNUMBER(SEARCH("DOUCEUR",B6))),"Douceur",IF(OR(ISNUMBER(SEARCH("SANGO",B6)),ISNUMBER(SEARCH("CS-SANGO",B6))),"SANGO",IF(ISNUMBER(SEARCH("BLANDOUX",B6)),"Blandoux",IF(ISNUMBER(SEARCH("SHIWAMI",B6)),"Shiwame",IF(ISNUMBER(SEARCH("KELLOGG",B6)),"Kelloggs",IF(OR(ISNUMBER(SEARCH("TOBIGO",B6)),ISNUMBER(SEARCH("DWIST",B6))),"Tobigo",IF(OR(ISNUMBER(SEARCH("MARISOL",B6)),ISNUMBER(SEARCH("MARESOL",B6))),"Maresol",IF(OR(ISNUMBER(SEARCH("TAKIS",B6)),ISNUMBER(SEARCH("TAKYS",B6))),"TAKYS",IF(ISNUMBER(SEARCH("TAWIL",B6)),"Tawil",IF(ISNUMBER(SEARCH("FROMY",B6)),"Fromy","")))))))))))))))))))))))) -> Tobigo | E6: Calin VP | F6: =COUNTIF(C:C,E6) -> 14
A7: =Products!A1229 -> CF35516 | B7: =Products!B1229 -> TOBIGO MUFFIN 30U - NC | C7: =IF(OR(ISNUMBER(SEARCH("SELHAM",B7)),ISNUMBER(SEARCH("LHAFLA",B7)),ISNUMBER(SEARCH("ZINE",B7)),ISNUMBER(SEARCH("tiyay",B7)),ISNUMBER(SEARCH("alouns",B7)),ISNUMBER(SEARCH("lmhrat",B7))),"The Al Itkane",IF(AND(ISNUMBER(SEARCH("CALIN",B7)),ISNUMBER(SEARCH("RP",B7)),NOT(ISNUMBER(SEARCH("VP",B7)))),"Calin RP",IF(AND(ISNUMBER(SEARCH("CALIN",B7)),ISNUMBER(SEARCH("VP",B7))),"Calin VP",IF(AND(ISNUMBER(SEARCH("MIO",B7)),OR(ISNUMBER(SEARCH("Vaisselle",B7)),ISNUMBER(SEARCH("vaisselle",B7)))),"Mio Liquid Vaisselle",IF(AND(ISNUMBER(SEARCH("MIO",B7)),ISNUMBER(SEARCH("Javel",B7))),"Mio Javel",IF(AND(ISNUMBER(SEARCH("MIO",B7)),ISNUMBER(SEARCH("Matic",B7))),"Mio Matic",IF(AND(ISNUMBER(SEARCH("MIO",B7)),OR(ISNUMBER(SEARCH("Détérgent",B7)),ISNUMBER(SEARCH("Poudre",B7)),ISNUMBER(SEARCH("Semi Auto",B7)),ISNUMBER(SEARCH("1KG",B7)),ISNUMBER(SEARCH("500G",B7)),ISNUMBER(SEARCH("10KG",B7)),ISNUMBER(SEARCH("1.5K",B7)),ISNUMBER(SEARCH("215G",B7)),ISNUMBER(SEARCH("350G",B7)),ISNUMBER(SEARCH("90G",B7)),ISNUMBER(SEARCH("Gold",B7)),ISNUMBER(SEARCH("Citron",B7)),ISNUMBER(SEARCH("Rose",B7)),ISNUMBER(SEARCH("Lessive",B7))),NOT(OR(ISNUMBER(SEARCH("Vaisselle",B7)),ISNUMBER(SEARCH("Javel",B7)),ISNUMBER(SEARCH("Matic",B7)),ISNUMBER(SEARCH("Nettoyant",B7)),ISNUMBER(SEARCH("Pâte",B7)),ISNUMBER(SEARCH("Lave",B7)),ISNUMBER(SEARCH("Détartrant",B7))))),"Mio main (1k+500gr)",IF(AND(ISNUMBER(SEARCH("PAPILLON",B7)),OR(ISNUMBER(SEARCH("Papier",B7)),ISNUMBER(SEARCH("Hygiénique",B7)),ISNUMBER(SEARCH("HYGIÉNIQUE",B7))),NOT(OR(ISNUMBER(SEARCH("Lingette",B7)),ISNUMBER(SEARCH("Mouchoir",B7))))),"Papillon Papier",IF(OR(ISNUMBER(SEARCH("TAJ AL SAHAR",B7)),ISNUMBER(SEARCH("TAJ BLADI",B7)),ISNUMBER(SEARCH("TAJ BELADI",B7)),ISNUMBER(SEARCH("Tilal Assahra",B7)),ISNUMBER(SEARCH("Jawharat Asahra",B7))),"TAJ SAHARA",IF(AND(OR(ISNUMBER(SEARCH("AL ITKANE",B7)),ISNUMBER(SEARCH("ALITKANE",B7)),ISNUMBER(SEARCH("PRESTO",B7))),NOT(OR(ISNUMBER(SEARCH("Thé",B7)),ISNUMBER(SEARCH("THE ",B7)),ISNUMBER(SEARCH("thé",B7)),ISNUMBER(SEARCH("SELHAM",B7)),ISNUMBER(SEARCH("LHAFLA",B7)),ISNUMBER(SEARCH("ZINE",B7)),ISNUMBER(SEARCH("tiyay",B7)),ISNUMBER(SEARCH("alouns",B7)),ISNUMBER(SEARCH("lmhrat",B7))))),"Al Itkrans + Presto",IF(OR(ISNUMBER(SEARCH("DALAA",B7)),ISNUMBER(SEARCH("CS-DALAA",B7)),ISNUMBER(SEARCH("DALINA",B7))),"Dalaa VP / Baqqal / RP",IF(OR(LEFT(UPPER(B7),4)="MIA ",LEFT(UPPER(B7),6)="CS-MIA"),"Mia",IF(OR(LEFT(UPPER(B7),5)="NOVA ",LEFT(UPPER(B7),7)="CS-NOVA"),"Nova",IF(OR(ISNUMBER(SEARCH("PRIMA ",B7)),ISNUMBER(SEARCH("CS-PRIMA",B7))),"Prima",IF(OR(ISNUMBER(SEARCH("Douceur",B7)),ISNUMBER(SEARCH("DOUCEUR",B7))),"Douceur",IF(OR(ISNUMBER(SEARCH("SANGO",B7)),ISNUMBER(SEARCH("CS-SANGO",B7))),"SANGO",IF(ISNUMBER(SEARCH("BLANDOUX",B7)),"Blandoux",IF(ISNUMBER(SEARCH("SHIWAMI",B7)),"Shiwame",IF(ISNUMBER(SEARCH("KELLOGG",B7)),"Kelloggs",IF(OR(ISNUMBER(SEARCH("TOBIGO",B7)),ISNUMBER(SEARCH("DWIST",B7))),"Tobigo",IF(OR(ISNUMBER(SEARCH("MARISOL",B7)),ISNUMBER(SEARCH("MARESOL",B7))),"Maresol",IF(OR(ISNUMBER(SEARCH("TAKIS",B7)),ISNUMBER(SEARCH("TAKYS",B7))),"TAKYS",IF(ISNUMBER(SEARCH("TAWIL",B7)),"Tawil",IF(ISNUMBER(SEARCH("FROMY",B7)),"Fromy","")))))))))))))))))))))))) -> Tobigo | E7: Nova | F7: =COUNTIF(C:C,E7) -> 11
A8: =Products!A1257 -> CF35517 | B8: =Products!B1257 -> TOBIGO TARTLET 24U - NC | C8: =IF(OR(ISNUMBER(SEARCH("SELHAM",B8)),ISNUMBER(SEARCH("LHAFLA",B8)),ISNUMBER(SEARCH("ZINE",B8)),ISNUMBER(SEARCH("tiyay",B8)),ISNUMBER(SEARCH("alouns",B8)),ISNUMBER(SEARCH("lmhrat",B8))),"The Al Itkane",IF(AND(ISNUMBER(SEARCH("CALIN",B8)),ISNUMBER(SEARCH("RP",B8)),NOT(ISNUMBER(SEARCH("VP",B8)))),"Calin RP",IF(AND(ISNUMBER(SEARCH("CALIN",B8)),ISNUMBER(SEARCH("VP",B8))),"Calin VP",IF(AND(ISNUMBER(SEARCH("MIO",B8)),OR(ISNUMBER(SEARCH("Vaisselle",B8)),ISNUMBER(SEARCH("vaisselle",B8)))),"Mio Liquid Vaisselle",IF(AND(ISNUMBER(SEARCH("MIO",B8)),ISNUMBER(SEARCH("Javel",B8))),"Mio Javel",IF(AND(ISNUMBER(SEARCH("MIO",B8)),ISNUMBER(SEARCH("Matic",B8))),"Mio Matic",IF(AND(ISNUMBER(SEARCH("MIO",B8)),OR(ISNUMBER(SEARCH("Détérgent",B8)),ISNUMBER(SEARCH("Poudre",B8)),ISNUMBER(SEARCH("Semi Auto",B8)),ISNUMBER(SEARCH("1KG",B8)),ISNUMBER(SEARCH("500G",B8)),ISNUMBER(SEARCH("10KG",B8)),ISNUMBER(SEARCH("1.5K",B8)),ISNUMBER(SEARCH("215G",B8)),ISNUMBER(SEARCH("350G",B8)),ISNUMBER(SEARCH("90G",B8)),ISNUMBER(SEARCH("Gold",B8)),ISNUMBER(SEARCH("Citron",B8)),ISNUMBER(SEARCH("Rose",B8)),ISNUMBER(SEARCH("Lessive",B8))),NOT(OR(ISNUMBER(SEARCH("Vaisselle",B8)),ISNUMBER(SEARCH("Javel",B8)),ISNUMBER(SEARCH("Matic",B8)),ISNUMBER(SEARCH("Nettoyant",B8)),ISNUMBER(SEARCH("Pâte",B8)),ISNUMBER(SEARCH("Lave",B8)),ISNUMBER(SEARCH("Détartrant",B8))))),"Mio main (1k+500gr)",IF(AND(ISNUMBER(SEARCH("PAPILLON",B8)),OR(ISNUMBER(SEARCH("Papier",B8)),ISNUMBER(SEARCH("Hygiénique",B8)),ISNUMBER(SEARCH("HYGIÉNIQUE",B8))),NOT(OR(ISNUMBER(SEARCH("Lingette",B8)),ISNUMBER(SEARCH("Mouchoir",B8))))),"Papillon Papier",IF(OR(ISNUMBER(SEARCH("TAJ AL SAHAR",B8)),ISNUMBER(SEARCH("TAJ BLADI",B8)),ISNUMBER(SEARCH("TAJ BELADI",B8)),ISNUMBER(SEARCH("Tilal Assahra",B8)),ISNUMBER(SEARCH("Jawharat Asahra",B8))),"TAJ SAHARA",IF(AND(OR(ISNUMBER(SEARCH("AL ITKANE",B8)),ISNUMBER(SEARCH("ALITKANE",B8)),ISNUMBER(SEARCH("PRESTO",B8))),NOT(OR(ISNUMBER(SEARCH("Thé",B8)),ISNUMBER(SEARCH("THE ",B8)),ISNUMBER(SEARCH("thé",B8)),ISNUMBER(SEARCH("SELHAM",B8)),ISNUMBER(SEARCH("LHAFLA",B8)),ISNUMBER(SEARCH("ZINE",B8)),ISNUMBER(SEARCH("tiyay",B8)),ISNUMBER(SEARCH("alouns",B8)),ISNUMBER(SEARCH("lmhrat",B8))))),"Al Itkrans + Presto",IF(OR(ISNUMBER(SEARCH("DALAA",B8)),ISNUMBER(SEARCH("CS-DALAA",B8)),ISNUMBER(SEARCH("DALINA",B8))),"Dalaa VP / Baqqal / RP",IF(OR(LEFT(UPPER(B8),4)="MIA ",LEFT(UPPER(B8),6)="CS-MIA"),"Mia",IF(OR(LEFT(UPPER(B8),5)="NOVA ",LEFT(UPPER(B8),7)="CS-NOVA"),"Nova",IF(OR(ISNUMBER(SEARCH("PRIMA ",B8)),ISNUMBER(SEARCH("CS-PRIMA",B8))),"Prima",IF(OR(ISNUMBER(SEARCH("Douceur",B8)),ISNUMBER(SEARCH("DOUCEUR",B8))),"Douceur",IF(OR(ISNUMBER(SEARCH("SANGO",B8)),ISNUMBER(SEARCH("CS-SANGO",B8))),"SANGO",IF(ISNUMBER(SEARCH("BLANDOUX",B8)),"Blandoux",IF(ISNUMBER(SEARCH("SHIWAMI",B8)),"Shiwame",IF(ISNUMBER(SEARCH("KELLOGG",B8)),"Kelloggs",IF(OR(ISNUMBER(SEARCH("TOBIGO",B8)),ISNUMBER(SEARCH("DWIST",B8))),"Tobigo",IF(OR(ISNUMBER(SEARCH("MARISOL",B8)),ISNUMBER(SEARCH("MARESOL",B8))),"Maresol",IF(OR(ISNUMBER(SEARCH("TAKIS",B8)),ISNUMBER(SEARCH("TAKYS",B8))),"TAKYS",IF(ISNUMBER(SEARCH("TAWIL",B8)),"Tawil",IF(ISNUMBER(SEARCH("FROMY",B8)),"Fromy","")))))))))))))))))))))))) -> Tobigo | E8: Prima | F8: =COUNTIF(C:C,E8) -> 7
A9: =Products!A1355 -> CF35518 | B9: =Products!B1355 -> TOBIGO DONUT 24U - NC | C9: =IF(OR(ISNUMBER(SEARCH("SELHAM",B9)),ISNUMBER(SEARCH("LHAFLA",B9)),ISNUMBER(SEARCH("ZINE",B9)),ISNUMBER(SEARCH("tiyay",B9)),ISNUMBER(SEARCH("alouns",B9)),ISNUMBER(SEARCH("lmhrat",B9))),"The Al Itkane",IF(AND(ISNUMBER(SEARCH("CALIN",B9)),ISNUMBER(SEARCH("RP",B9)),NOT(ISNUMBER(SEARCH("VP",B9)))),"Calin RP",IF(AND(ISNUMBER(SEARCH("CALIN",B9)),ISNUMBER(SEARCH("VP",B9))),"Calin VP",IF(AND(ISNUMBER(SEARCH("MIO",B9)),OR(ISNUMBER(SEARCH("Vaisselle",B9)),ISNUMBER(SEARCH("vaisselle",B9)))),"Mio Liquid Vaisselle",IF(AND(ISNUMBER(SEARCH("MIO",B9)),ISNUMBER(SEARCH("Javel",B9))),"Mio Javel",IF(AND(ISNUMBER(SEARCH("MIO",B9)),ISNUMBER(SEARCH("Matic",B9))),"Mio Matic",IF(AND(ISNUMBER(SEARCH("MIO",B9)),OR(ISNUMBER(SEARCH("Détérgent",B9)),ISNUMBER(SEARCH("Poudre",B9)),ISNUMBER(SEARCH("Semi Auto",B9)),ISNUMBER(SEARCH("1KG",B9)),ISNUMBER(SEARCH("500G",B9)),ISNUMBER(SEARCH("10KG",B9)),ISNUMBER(SEARCH("1.5K",B9)),ISNUMBER(SEARCH("215G",B9)),ISNUMBER(SEARCH("350G",B9)),ISNUMBER(SEARCH("90G",B9)),ISNUMBER(SEARCH("Gold",B9)),ISNUMBER(SEARCH("Citron",B9)),ISNUMBER(SEARCH("Rose",B9)),ISNUMBER(SEARCH("Lessive",B9))),NOT(OR(ISNUMBER(SEARCH("Vaisselle",B9)),ISNUMBER(SEARCH("Javel",B9)),ISNUMBER(SEARCH("Matic",B9)),ISNUMBER(SEARCH("Nettoyant",B9)),ISNUMBER(SEARCH("Pâte",B9)),ISNUMBER(SEARCH("Lave",B9)),ISNUMBER(SEARCH("Détartrant",B9))))),"Mio main (1k+500gr)",IF(AND(ISNUMBER(SEARCH("PAPILLON",B9)),OR(ISNUMBER(SEARCH("Papier",B9)),ISNUMBER(SEARCH("Hygiénique",B9)),ISNUMBER(SEARCH("HYGIÉNIQUE",B9))),NOT(OR(ISNUMBER(SEARCH("Lingette",B9)),ISNUMBER(SEARCH("Mouchoir",B9))))),"Papillon Papier",IF(OR(ISNUMBER(SEARCH("TAJ AL SAHAR",B9)),ISNUMBER(SEARCH("TAJ BLADI",B9)),ISNUMBER(SEARCH("TAJ BELADI",B9)),ISNUMBER(SEARCH("Tilal Assahra",B9)),ISNUMBER(SEARCH("Jawharat Asahra",B9))),"TAJ SAHARA",IF(AND(OR(ISNUMBER(SEARCH("AL ITKANE",B9)),ISNUMBER(SEARCH("ALITKANE",B9)),ISNUMBER(SEARCH("PRESTO",B9))),NOT(OR(ISNUMBER(SEARCH("Thé",B9)),ISNUMBER(SEARCH("THE ",B9)),ISNUMBER(SEARCH("thé",B9)),ISNUMBER(SEARCH("SELHAM",B9)),ISNUMBER(SEARCH("LHAFLA",B9)),ISNUMBER(SEARCH("ZINE",B9)),ISNUMBER(SEARCH("tiyay",B9)),ISNUMBER(SEARCH("alouns",B9)),ISNUMBER(SEARCH("lmhrat",B9))))),"Al Itkrans + Presto",IF(OR(ISNUMBER(SEARCH("DALAA",B9)),ISNUMBER(SEARCH("CS-DALAA",B9)),ISNUMBER(SEARCH("DALINA",B9))),"Dalaa VP / Baqqal / RP",IF(OR(LEFT(UPPER(B9),4)="MIA ",LEFT(UPPER(B9),6)="CS-MIA"),"Mia",IF(OR(LEFT(UPPER(B9),5)="NOVA ",LEFT(UPPER(B9),7)="CS-NOVA"),"Nova",IF(OR(ISNUMBER(SEARCH("PRIMA ",B9)),ISNUMBER(SEARCH("CS-PRIMA",B9))),"Prima",IF(OR(ISNUMBER(SEARCH("Douceur",B9)),ISNUMBER(SEARCH("DOUCEUR",B9))),"Douceur",IF(OR(ISNUMBER(SEARCH("SANGO",B9)),ISNUMBER(SEARCH("CS-SANGO",B9))),"SANGO",IF(ISNUMBER(SEARCH("BLANDOUX",B9)),"Blandoux",IF(ISNUMBER(SEARCH("SHIWAMI",B9)),"Shiwame",IF(ISNUMBER(SEARCH("KELLOGG",B9)),"Kelloggs",IF(OR(ISNUMBER(SEARCH("TOBIGO",B9)),ISNUMBER(SEARCH("DWIST",B9))),"Tobigo",IF(OR(ISNUMBER(SEARCH("MARISOL",B9)),ISNUMBER(SEARCH("MARESOL",B9))),"Maresol",IF(OR(ISNUMBER(SEARCH("TAKIS",B9)),ISNUMBER(SEARCH("TAKYS",B9))),"TAKYS",IF(ISNUMBER(SEARCH("TAWIL",B9)),"Tawil",IF(ISNUMBER(SEARCH("FROMY",B9)),"Fromy","")))))))))))))))))))))))) -> Tobigo | E9: Mio Liquid Vaisselle | F9: =COUNTIF(C:C,E9) -> 16
A10: =Products!A1422 -> ART00221 | B10: =Products!B1422 -> TOBIGO Crousty Lemon Cream | C10: =IF(OR(ISNUMBER(SEARCH("SELHAM",B10)),ISNUMBER(SEARCH("LHAFLA",B10)),ISNUMBER(SEARCH("ZINE",B10)),ISNUMBER(SEARCH("tiyay",B10)),ISNUMBER(SEARCH("alouns",B10)),ISNUMBER(SEARCH("lmhrat",B10))),"The Al Itkane",IF(AND(ISNUMBER(SEARCH("CALIN",B10)),ISNUMBER(SEARCH("RP",B10)),NOT(ISNUMBER(SEARCH("VP",B10)))),"Calin RP",IF(AND(ISNUMBER(SEARCH("CALIN",B10)),ISNUMBER(SEARCH("VP",B10))),"Calin VP",IF(AND(ISNUMBER(SEARCH("MIO",B10)),OR(ISNUMBER(SEARCH("Vaisselle",B10)),ISNUMBER(SEARCH("vaisselle",B10)))),"Mio Liquid Vaisselle",IF(AND(ISNUMBER(SEARCH("MIO",B10)),ISNUMBER(SEARCH("Javel",B10))),"Mio Javel",IF(AND(ISNUMBER(SEARCH("MIO",B10)),ISNUMBER(SEARCH("Matic",B10))),"Mio Matic",IF(AND(ISNUMBER(SEARCH("MIO",B10)),OR(ISNUMBER(SEARCH("Détérgent",B10)),ISNUMBER(SEARCH("Poudre",B10)),ISNUMBER(SEARCH("Semi Auto",B10)),ISNUMBER(SEARCH("1KG",B10)),ISNUMBER(SEARCH("500G",B10)),ISNUMBER(SEARCH("10KG",B10)),ISNUMBER(SEARCH("1.5K",B10)),ISNUMBER(SEARCH("215G",B10)),ISNUMBER(SEARCH("350G",B10)),ISNUMBER(SEARCH("90G",B10)),ISNUMBER(SEARCH("Gold",B10)),ISNUMBER(SEARCH("Citron",B10)),ISNUMBER(SEARCH("Rose",B10)),ISNUMBER(SEARCH("Lessive",B10))),NOT(OR(ISNUMBER(SEARCH("Vaisselle",B10)),ISNUMBER(SEARCH("Javel",B10)),ISNUMBER(SEARCH("Matic",B10)),ISNUMBER(SEARCH("Nettoyant",B10)),ISNUMBER(SEARCH("Pâte",B10)),ISNUMBER(SEARCH("Lave",B10)),ISNUMBER(SEARCH("Détartrant",B10))))),"Mio main (1k+500gr)",IF(AND(ISNUMBER(SEARCH("PAPILLON",B10)),OR(ISNUMBER(SEARCH("Papier",B10)),ISNUMBER(SEARCH("Hygiénique",B10)),ISNUMBER(SEARCH("HYGIÉNIQUE",B10))),NOT(OR(ISNUMBER(SEARCH("Lingette",B10)),ISNUMBER(SEARCH("Mouchoir",B10))))),"Papillon Papier",IF(OR(ISNUMBER(SEARCH("TAJ AL SAHAR",B10)),ISNUMBER(SEARCH("TAJ BLADI",B10)),ISNUMBER(SEARCH("TAJ BELADI",B10)),ISNUMBER(SEARCH("Tilal Assahra",B10)),ISNUMBER(SEARCH("Jawharat Asahra",B10))),"TAJ SAHARA",IF(AND(OR(ISNUMBER(SEARCH("AL ITKANE",B10)),ISNUMBER(SEARCH("ALITKANE",B10)),ISNUMBER(SEARCH("PRESTO",B10))),NOT(OR(ISNUMBER(SEARCH("Thé",B10)),ISNUMBER(SEARCH("THE ",B10)),ISNUMBER(SEARCH("thé",B10)),ISNUMBER(SEARCH("SELHAM",B10)),ISNUMBER(SEARCH("LHAFLA",B10)),ISNUMBER(SEARCH("ZINE",B10)),ISNUMBER(SEARCH("tiyay",B10)),ISNUMBER(SEARCH("alouns",B10)),ISNUMBER(SEARCH("lmhrat",B10))))),"Al Itkrans + Presto",IF(OR(ISNUMBER(SEARCH("DALAA",B10)),ISNUMBER(SEARCH("CS-DALAA",B10)),ISNUMBER(SEARCH("DALINA",B10))),"Dalaa VP / Baqqal / RP",IF(OR(LEFT(UPPER(B10),4)="MIA ",LEFT(UPPER(B10),6)="CS-MIA"),"Mia",IF(OR(LEFT(UPPER(B10),5)="NOVA ",LEFT(UPPER(B10),7)="CS-NOVA"),"Nova",IF(OR(ISNUMBER(SEARCH("PRIMA ",B10)),ISNUMBER(SEARCH("CS-PRIMA",B10))),"Prima",IF(OR(ISNUMBER(SEARCH("Douceur",B10)),ISNUMBER(SEARCH("DOUCEUR",B10))),"Douceur",IF(OR(ISNUMBER(SEARCH("SANGO",B10)),ISNUMBER(SEARCH("CS-SANGO",B10))),"SANGO",IF(ISNUMBER(SEARCH("BLANDOUX",B10)),"Blandoux",IF(ISNUMBER(SEARCH("SHIWAMI",B10)),"Shiwame",IF(ISNUMBER(SEARCH("KELLOGG",B10)),"Kelloggs",IF(OR(ISNUMBER(SEARCH("TOBIGO",B10)),ISNUMBER(SEARCH("DWIST",B10))),"Tobigo",IF(OR(ISNUMBER(SEARCH("MARISOL",B10)),ISNUMBER(SEARCH("MARESOL",B10))),"Maresol",IF(OR(ISNUMBER(SEARCH("TAKIS",B10)),ISNUMBER(SEARCH("TAKYS",B10))),"TAKYS",IF(ISNUMBER(SEARCH("TAWIL",B10)),"Tawil",IF(ISNUMBER(SEARCH("FROMY",B10)),"Fromy","")))))))))))))))))))))))) -> Tobigo | E10: Mio Javel | F10: =COUNTIF(C:C,E10) -> 13
A11: =Products!A1423 -> ART00222 | B11: =Products!B1423 -> TOBIGO Pyramido All Black | C11: =IF(OR(ISNUMBER(SEARCH("SELHAM",B11)),ISNUMBER(SEARCH("LHAFLA",B11)),ISNUMBER(SEARCH("ZINE",B11)),ISNUMBER(SEARCH("tiyay",B11)),ISNUMBER(SEARCH("alouns",B11)),ISNUMBER(SEARCH("lmhrat",B11))),"The Al Itkane",IF(AND(ISNUMBER(SEARCH("CALIN",B11)),ISNUMBER(SEARCH("RP",B11)),NOT(ISNUMBER(SEARCH("VP",B11)))),"Calin RP",IF(AND(ISNUMBER(SEARCH("CALIN",B11)),ISNUMBER(SEARCH("VP",B11))),"Calin VP",IF(AND(ISNUMBER(SEARCH("MIO",B11)),OR(ISNUMBER(SEARCH("Vaisselle",B11)),ISNUMBER(SEARCH("vaisselle",B11)))),"Mio Liquid Vaisselle",IF(AND(ISNUMBER(SEARCH("MIO",B11)),ISNUMBER(SEARCH("Javel",B11))),"Mio Javel",IF(AND(ISNUMBER(SEARCH("MIO",B11)),ISNUMBER(SEARCH("Matic",B11))),"Mio Matic",IF(AND(ISNUMBER(SEARCH("MIO",B11)),OR(ISNUMBER(SEARCH("Détérgent",B11)),ISNUMBER(SEARCH("Poudre",B11)),ISNUMBER(SEARCH("Semi Auto",B11)),ISNUMBER(SEARCH("1KG",B11)),ISNUMBER(SEARCH("500G",B11)),ISNUMBER(SEARCH("10KG",B11)),ISNUMBER(SEARCH("1.5K",B11)),ISNUMBER(SEARCH("215G",B11)),ISNUMBER(SEARCH("350G",B11)),ISNUMBER(SEARCH("90G",B11)),ISNUMBER(SEARCH("Gold",B11)),ISNUMBER(SEARCH("Citron",B11)),ISNUMBER(SEARCH("Rose",B11)),ISNUMBER(SEARCH("Lessive",B11))),NOT(OR(ISNUMBER(SEARCH("Vaisselle",B11)),ISNUMBER(SEARCH("Javel",B11)),ISNUMBER(SEARCH("Matic",B11)),ISNUMBER(SEARCH("Nettoyant",B11)),ISNUMBER(SEARCH("Pâte",B11)),ISNUMBER(SEARCH("Lave",B11)),ISNUMBER(SEARCH("Détartrant",B11))))),"Mio main (1k+500gr)",IF(AND(ISNUMBER(SEARCH("PAPILLON",B11)),OR(ISNUMBER(SEARCH("Papier",B11)),ISNUMBER(SEARCH("Hygiénique",B11)),ISNUMBER(SEARCH("HYGIÉNIQUE",B11))),NOT(OR(ISNUMBER(SEARCH("Lingette",B11)),ISNUMBER(SEARCH("Mouchoir",B11))))),"Papillon Papier",IF(OR(ISNUMBER(SEARCH("TAJ AL SAHAR",B11)),ISNUMBER(SEARCH("TAJ BLADI",B11)),ISNUMBER(SEARCH("TAJ BELADI",B11)),ISNUMBER(SEARCH("Tilal Assahra",B11)),ISNUMBER(SEARCH("Jawharat Asahra",B11))),"TAJ SAHARA",IF(AND(OR(ISNUMBER(SEARCH("AL ITKANE",B11)),ISNUMBER(SEARCH("ALITKANE",B11)),ISNUMBER(SEARCH("PRESTO",B11))),NOT(OR(ISNUMBER(SEARCH("Thé",B11)),ISNUMBER(SEARCH("THE ",B11)),ISNUMBER(SEARCH("thé",B11)),ISNUMBER(SEARCH("SELHAM",B11)),ISNUMBER(SEARCH("LHAFLA",B11)),ISNUMBER(SEARCH("ZINE",B11)),ISNUMBER(SEARCH("tiyay",B11)),ISNUMBER(SEARCH("alouns",B11)),ISNUMBER(SEARCH("lmhrat",B11))))),"Al Itkrans + Presto",IF(OR(ISNUMBER(SEARCH("DALAA",B11)),ISNUMBER(SEARCH("CS-DALAA",B11)),ISNUMBER(SEARCH("DALINA",B11))),"Dalaa VP / Baqqal / RP",IF(OR(LEFT(UPPER(B11),4)="MIA ",LEFT(UPPER(B11),6)="CS-MIA"),"Mia",IF(OR(LEFT(UPPER(B11),5)="NOVA ",LEFT(UPPER(B11),7)="CS-NOVA"),"Nova",IF(OR(ISNUMBER(SEARCH("PRIMA ",B11)),ISNUMBER(SEARCH("CS-PRIMA",B11))),"Prima",IF(OR(ISNUMBER(SEARCH("Douceur",B11)),ISNUMBER(SEARCH("DOUCEUR",B11))),"Douceur",IF(OR(ISNUMBER(SEARCH("SANGO",B11)),ISNUMBER(SEARCH("CS-SANGO",B11))),"SANGO",IF(ISNUMBER(SEARCH("BLANDOUX",B11)),"Blandoux",IF(ISNUMBER(SEARCH("SHIWAMI",B11)),"Shiwame",IF(ISNUMBER(SEARCH("KELLOGG",B11)),"Kelloggs",IF(OR(ISNUMBER(SEARCH("TOBIGO",B11)),ISNUMBER(SEARCH("DWIST",B11))),"Tobigo",IF(OR(ISNUMBER(SEARCH("MARISOL",B11)),ISNUMBER(SEARCH("MARESOL",B11))),"Maresol",IF(OR(ISNUMBER(SEARCH("TAKIS",B11)),ISNUMBER(SEARCH("TAKYS",B11))),"TAKYS",IF(ISNUMBER(SEARCH("TAWIL",B11)),"Tawil",IF(ISNUMBER(SEARCH("FROMY",B11)),"Fromy","")))))))))))))))))))))))) -> Tobigo | E11: Douceur | F11: =COUNTIF(C:C,E11) -> 8
A12: =Products!A1424 -> ART00223 | B12: =Products!B1424 -> TOBIGO Pyramido Lemon | C12: =IF(OR(ISNUMBER(SEARCH("SELHAM",B12)),ISNUMBER(SEARCH("LHAFLA",B12)),ISNUMBER(SEARCH("ZINE",B12)),ISNUMBER(SEARCH("tiyay",B12)),ISNUMBER(SEARCH("alouns",B12)),ISNUMBER(SEARCH("lmhrat",B12))),"The Al Itkane",IF(AND(ISNUMBER(SEARCH("CALIN",B12)),ISNUMBER(SEARCH("RP",B12)),NOT(ISNUMBER(SEARCH("VP",B12)))),"Calin RP",IF(AND(ISNUMBER(SEARCH("CALIN",B12)),ISNUMBER(SEARCH("VP",B12))),"Calin VP",IF(AND(ISNUMBER(SEARCH("MIO",B12)),OR(ISNUMBER(SEARCH("Vaisselle",B12)),ISNUMBER(SEARCH("vaisselle",B12)))),"Mio Liquid Vaisselle",IF(AND(ISNUMBER(SEARCH("MIO",B12)),ISNUMBER(SEARCH("Javel",B12))),"Mio Javel",IF(AND(ISNUMBER(SEARCH("MIO",B12)),ISNUMBER(SEARCH("Matic",B12))),"Mio Matic",IF(AND(ISNUMBER(SEARCH("MIO",B12)),OR(ISNUMBER(SEARCH("Détérgent",B12)),ISNUMBER(SEARCH("Poudre",B12)),ISNUMBER(SEARCH("Semi Auto",B12)),ISNUMBER(SEARCH("1KG",B12)),ISNUMBER(SEARCH("500G",B12)),ISNUMBER(SEARCH("10KG",B12)),ISNUMBER(SEARCH("1.5K",B12)),ISNUMBER(SEARCH("215G",B12)),ISNUMBER(SEARCH("350G",B12)),ISNUMBER(SEARCH("90G",B12)),ISNUMBER(SEARCH("Gold",B12)),ISNUMBER(SEARCH("Citron",B12)),ISNUMBER(SEARCH("Rose",B12)),ISNUMBER(SEARCH("Lessive",B12))),NOT(OR(ISNUMBER(SEARCH("Vaisselle",B12)),ISNUMBER(SEARCH("Javel",B12)),ISNUMBER(SEARCH("Matic",B12)),ISNUMBER(SEARCH("Nettoyant",B12)),ISNUMBER(SEARCH("Pâte",B12)),ISNUMBER(SEARCH("Lave",B12)),ISNUMBER(SEARCH("Détartrant",B12))))),"Mio main (1k+500gr)",IF(AND(ISNUMBER(SEARCH("PAPILLON",B12)),OR(ISNUMBER(SEARCH("Papier",B12)),ISNUMBER(SEARCH("Hygiénique",B12)),ISNUMBER(SEARCH("HYGIÉNIQUE",B12))),NOT(OR(ISNUMBER(SEARCH("Lingette",B12)),ISNUMBER(SEARCH("Mouchoir",B12))))),"Papillon Papier",IF(OR(ISNUMBER(SEARCH("TAJ AL SAHAR",B12)),ISNUMBER(SEARCH("TAJ BLADI",B12)),ISNUMBER(SEARCH("TAJ BELADI",B12)),ISNUMBER(SEARCH("Tilal Assahra",B12)),ISNUMBER(SEARCH("Jawharat Asahra",B12))),"TAJ SAHARA",IF(AND(OR(ISNUMBER(SEARCH("AL ITKANE",B12)),ISNUMBER(SEARCH("ALITKANE",B12)),ISNUMBER(SEARCH("PRESTO",B12))),NOT(OR(ISNUMBER(SEARCH("Thé",B12)),ISNUMBER(SEARCH("THE ",B12)),ISNUMBER(SEARCH("thé",B12)),ISNUMBER(SEARCH("SELHAM",B12)),ISNUMBER(SEARCH("LHAFLA",B12)),ISNUMBER(SEARCH("ZINE",B12)),ISNUMBER(SEARCH("tiyay",B12)),ISNUMBER(SEARCH("alouns",B12)),ISNUMBER(SEARCH("lmhrat",B12))))),"Al Itkrans + Presto",IF(OR(ISNUMBER(SEARCH("DALAA",B12)),ISNUMBER(SEARCH("CS-DALAA",B12)),ISNUMBER(SEARCH("DALINA",B12))),"Dalaa VP / Baqqal / RP",IF(OR(LEFT(UPPER(B12),4)="MIA ",LEFT(UPPER(B12),6)="CS-MIA"),"Mia",IF(OR(LEFT(UPPER(B12),5)="NOVA ",LEFT(UPPER(B12),7)="CS-NOVA"),"Nova",IF(OR(ISNUMBER(SEARCH("PRIMA ",B12)),ISNUMBER(SEARCH("CS-PRIMA",B12))),"Prima",IF(OR(ISNUMBER(SEARCH("Douceur",B12)),ISNUMBER(SEARCH("DOUCEUR",B12))),"Douceur",IF(OR(ISNUMBER(SEARCH("SANGO",B12)),ISNUMBER(SEARCH("CS-SANGO",B12))),"SANGO",IF(ISNUMBER(SEARCH("BLANDOUX",B12)),"Blandoux",IF(ISNUMBER(SEARCH("SHIWAMI",B12)),"Shiwame",IF(ISNUMBER(SEARCH("KELLOGG",B12)),"Kelloggs",IF(OR(ISNUMBER(SEARCH("TOBIGO",B12)),ISNUMBER(SEARCH("DWIST",B12))),"Tobigo",IF(OR(ISNUMBER(SEARCH("MARISOL",B12)),ISNUMBER(SEARCH("MARESOL",B12))),"Maresol",IF(OR(ISNUMBER(SEARCH("TAKIS",B12)),ISNUMBER(SEARCH("TAKYS",B12))),"TAKYS",IF(ISNUMBER(SEARCH("TAWIL",B12)),"Tawil",IF(ISNUMBER(SEARCH("FROMY",B12)),"Fromy","")))))))))))))))))))))))) -> Tobigo | E12: Mio Matic | F12: =COUNTIF(C:C,E12) -> 17
A13: =Products!A1425 -> ART00224 | B13: =Products!B1425 -> TOBIGO Chookies | C13: =IF(OR(ISNUMBER(SEARCH("SELHAM",B13)),ISNUMBER(SEARCH("LHAFLA",B13)),ISNUMBER(SEARCH("ZINE",B13)),ISNUMBER(SEARCH("tiyay",B13)),ISNUMBER(SEARCH("alouns",B13)),ISNUMBER(SEARCH("lmhrat",B13))),"The Al Itkane",IF(AND(ISNUMBER(SEARCH("CALIN",B13)),ISNUMBER(SEARCH("RP",B13)),NOT(ISNUMBER(SEARCH("VP",B13)))),"Calin RP",IF(AND(ISNUMBER(SEARCH("CALIN",B13)),ISNUMBER(SEARCH("VP",B13))),"Calin VP",IF(AND(ISNUMBER(SEARCH("MIO",B13)),OR(ISNUMBER(SEARCH("Vaisselle",B13)),ISNUMBER(SEARCH("vaisselle",B13)))),"Mio Liquid Vaisselle",IF(AND(ISNUMBER(SEARCH("MIO",B13)),ISNUMBER(SEARCH("Javel",B13))),"Mio Javel",IF(AND(ISNUMBER(SEARCH("MIO",B13)),ISNUMBER(SEARCH("Matic",B13))),"Mio Matic",IF(AND(ISNUMBER(SEARCH("MIO",B13)),OR(ISNUMBER(SEARCH("Détérgent",B13)),ISNUMBER(SEARCH("Poudre",B13)),ISNUMBER(SEARCH("Semi Auto",B13)),ISNUMBER(SEARCH("1KG",B13)),ISNUMBER(SEARCH("500G",B13)),ISNUMBER(SEARCH("10KG",B13)),ISNUMBER(SEARCH("1.5K",B13)),ISNUMBER(SEARCH("215G",B13)),ISNUMBER(SEARCH("350G",B13)),ISNUMBER(SEARCH("90G",B13)),ISNUMBER(SEARCH("Gold",B13)),ISNUMBER(SEARCH("Citron",B13)),ISNUMBER(SEARCH("Rose",B13)),ISNUMBER(SEARCH("Lessive",B13))),NOT(OR(ISNUMBER(SEARCH("Vaisselle",B13)),ISNUMBER(SEARCH("Javel",B13)),ISNUMBER(SEARCH("Matic",B13)),ISNUMBER(SEARCH("Nettoyant",B13)),ISNUMBER(SEARCH("Pâte",B13)),ISNUMBER(SEARCH("Lave",B13)),ISNUMBER(SEARCH("Détartrant",B13))))),"Mio main (1k+500gr)",IF(AND(ISNUMBER(SEARCH("PAPILLON",B13)),OR(ISNUMBER(SEARCH("Papier",B13)),ISNUMBER(SEARCH("Hygiénique",B13)),ISNUMBER(SEARCH("HYGIÉNIQUE",B13))),NOT(OR(ISNUMBER(SEARCH("Lingette",B13)),ISNUMBER(SEARCH("Mouchoir",B13))))),"Papillon Papier",IF(OR(ISNUMBER(SEARCH("TAJ AL SAHAR",B13)),ISNUMBER(SEARCH("TAJ BLADI",B13)),ISNUMBER(SEARCH("TAJ BELADI",B13)),ISNUMBER(SEARCH("Tilal Assahra",B13)),ISNUMBER(SEARCH("Jawharat Asahra",B13))),"TAJ SAHARA",IF(AND(OR(ISNUMBER(SEARCH("AL ITKANE",B13)),ISNUMBER(SEARCH("ALITKANE",B13)),ISNUMBER(SEARCH("PRESTO",B13))),NOT(OR(ISNUMBER(SEARCH("Thé",B13)),ISNUMBER(SEARCH("THE ",B13)),ISNUMBER(SEARCH("thé",B13)),ISNUMBER(SEARCH("SELHAM",B13)),ISNUMBER(SEARCH("LHAFLA",B13)),ISNUMBER(SEARCH("ZINE",B13)),ISNUMBER(SEARCH("tiyay",B13)),ISNUMBER(SEARCH("alouns",B13)),ISNUMBER(SEARCH("lmhrat",B13))))),"Al Itkrans + Presto",IF(OR(ISNUMBER(SEARCH("DALAA",B13)),ISNUMBER(SEARCH("CS-DALAA",B13)),ISNUMBER(SEARCH("DALINA",B13))),"Dalaa VP / Baqqal / RP",IF(OR(LEFT(UPPER(B13),4)="MIA ",LEFT(UPPER(B13),6)="CS-MIA"),"Mia",IF(OR(LEFT(UPPER(B13),5)="NOVA ",LEFT(UPPER(B13),7)="CS-NOVA"),"Nova",IF(OR(ISNUMBER(SEARCH("PRIMA ",B13)),ISNUMBER(SEARCH("CS-PRIMA",B13))),"Prima",IF(OR(ISNUMBER(SEARCH("Douceur",B13)),ISNUMBER(SEARCH("DOUCEUR",B13))),"Douceur",IF(OR(ISNUMBER(SEARCH("SANGO",B13)),ISNUMBER(SEARCH("CS-SANGO",B13))),"SANGO",IF(ISNUMBER(SEARCH("BLANDOUX",B13)),"Blandoux",IF(ISNUMBER(SEARCH("SHIWAMI",B13)),"Shiwame",IF(ISNUMBER(SEARCH("KELLOGG",B13)),"Kelloggs",IF(OR(ISNUMBER(SEARCH("TOBIGO",B13)),ISNUMBER(SEARCH("DWIST",B13))),"Tobigo",IF(OR(ISNUMBER(SEARCH("MARISOL",B13)),ISNUMBER(SEARCH("MARESOL",B13))),"Maresol",IF(OR(ISNUMBER(SEARCH("TAKIS",B13)),ISNUMBER(SEARCH("TAKYS",B13))),"TAKYS",IF(ISNUMBER(SEARCH("TAWIL",B13)),"Tawil",IF(ISNUMBER(SEARCH("FROMY",B13)),"Fromy","")))))))))))))))))))))))) -> Tobigo | E13: Papillon Papier | F13: =COUNTIF(C:C,E13) -> 4
A14: =Products!A1426 -> ART00225 | B14: =Products!B1426 -> TOBIGO Pyramido Milk Chocolate | C14: =IF(OR(ISNUMBER(SEARCH("SELHAM",B14)),ISNUMBER(SEARCH("LHAFLA",B14)),ISNUMBER(SEARCH("ZINE",B14)),ISNUMBER(SEARCH("tiyay",B14)),ISNUMBER(SEARCH("alouns",B14)),ISNUMBER(SEARCH("lmhrat",B14))),"The Al Itkane",IF(AND(ISNUMBER(SEARCH("CALIN",B14)),ISNUMBER(SEARCH("RP",B14)),NOT(ISNUMBER(SEARCH("VP",B14)))),"Calin RP",IF(AND(ISNUMBER(SEARCH("CALIN",B14)),ISNUMBER(SEARCH("VP",B14))),"Calin VP",IF(AND(ISNUMBER(SEARCH("MIO",B14)),OR(ISNUMBER(SEARCH("Vaisselle",B14)),ISNUMBER(SEARCH("vaisselle",B14)))),"Mio Liquid Vaisselle",IF(AND(ISNUMBER(SEARCH("MIO",B14)),ISNUMBER(SEARCH("Javel",B14))),"Mio Javel",IF(AND(ISNUMBER(SEARCH("MIO",B14)),ISNUMBER(SEARCH("Matic",B14))),"Mio Matic",IF(AND(ISNUMBER(SEARCH("MIO",B14)),OR(ISNUMBER(SEARCH("Détérgent",B14)),ISNUMBER(SEARCH("Poudre",B14)),ISNUMBER(SEARCH("Semi Auto",B14)),ISNUMBER(SEARCH("1KG",B14)),ISNUMBER(SEARCH("500G",B14)),ISNUMBER(SEARCH("10KG",B14)),ISNUMBER(SEARCH("1.5K",B14)),ISNUMBER(SEARCH("215G",B14)),ISNUMBER(SEARCH("350G",B14)),ISNUMBER(SEARCH("90G",B14)),ISNUMBER(SEARCH("Gold",B14)),ISNUMBER(SEARCH("Citron",B14)),ISNUMBER(SEARCH("Rose",B14)),ISNUMBER(SEARCH("Lessive",B14))),NOT(OR(ISNUMBER(SEARCH("Vaisselle",B14)),ISNUMBER(SEARCH("Javel",B14)),ISNUMBER(SEARCH("Matic",B14)),ISNUMBER(SEARCH("Nettoyant",B14)),ISNUMBER(SEARCH("Pâte",B14)),ISNUMBER(SEARCH("Lave",B14)),ISNUMBER(SEARCH("Détartrant",B14))))),"Mio main (1k+500gr)",IF(AND(ISNUMBER(SEARCH("PAPILLON",B14)),OR(ISNUMBER(SEARCH("Papier",B14)),ISNUMBER(SEARCH("Hygiénique",B14)),ISNUMBER(SEARCH("HYGIÉNIQUE",B14))),NOT(OR(ISNUMBER(SEARCH("Lingette",B14)),ISNUMBER(SEARCH("Mouchoir",B14))))),"Papillon Papier",IF(OR(ISNUMBER(SEARCH("TAJ AL SAHAR",B14)),ISNUMBER(SEARCH("TAJ BLADI",B14)),ISNUMBER(SEARCH("TAJ BELADI",B14)),ISNUMBER(SEARCH("Tilal Assahra",B14)),ISNUMBER(SEARCH("Jawharat Asahra",B14))),"TAJ SAHARA",IF(AND(OR(ISNUMBER(SEARCH("AL ITKANE",B14)),ISNUMBER(SEARCH("ALITKANE",B14)),ISNUMBER(SEARCH("PRESTO",B14))),NOT(OR(ISNUMBER(SEARCH("Thé",B14)),ISNUMBER(SEARCH("THE ",B14)),ISNUMBER(SEARCH("thé",B14)),ISNUMBER(SEARCH("SELHAM",B14)),ISNUMBER(SEARCH("LHAFLA",B14)),ISNUMBER(SEARCH("ZINE",B14)),ISNUMBER(SEARCH("tiyay",B14)),ISNUMBER(SEARCH("alouns",B14)),ISNUMBER(SEARCH("lmhrat",B14))))),"Al Itkrans + Presto",IF(OR(ISNUMBER(SEARCH("DALAA",B14)),ISNUMBER(SEARCH("CS-DALAA",B14)),ISNUMBER(SEARCH("DALINA",B14))),"Dalaa VP / Baqqal / RP",IF(OR(LEFT(UPPER(B14),4)="MIA ",LEFT(UPPER(B14),6)="CS-MIA"),"Mia",IF(OR(LEFT(UPPER(B14),5)="NOVA ",LEFT(UPPER(B14),7)="CS-NOVA"),"Nova",IF(OR(ISNUMBER(SEARCH("PRIMA ",B14)),ISNUMBER(SEARCH("CS-PRIMA",B14))),"Prima",IF(OR(ISNUMBER(SEARCH("Douceur",B14)),ISNUMBER(SEARCH("DOUCEUR",B14))),"Douceur",IF(OR(ISNUMBER(SEARCH("SANGO",B14)),ISNUMBER(SEARCH("CS-SANGO",B14))),"SANGO",IF(ISNUMBER(SEARCH("BLANDOUX",B14)),"Blandoux",IF(ISNUMBER(SEARCH("SHIWAMI",B14)),"Shiwame",IF(ISNUMBER(SEARCH("KELLOGG",B14)),"Kelloggs",IF(OR(ISNUMBER(SEARCH("TOBIGO",B14)),ISNUMBER(SEARCH("DWIST",B14))),"Tobigo",IF(OR(ISNUMBER(SEARCH("MARISOL",B14)),ISNUMBER(SEARCH("MARESOL",B14))),"Maresol",IF(OR(ISNUMBER(SEARCH("TAKIS",B14)),ISNUMBER(SEARCH("TAKYS",B14))),"TAKYS",IF(ISNUMBER(SEARCH("TAWIL",B14)),"Tawil",IF(ISNUMBER(SEARCH("FROMY",B14)),"Fromy","")))))))))))))))))))))))) -> Tobigo | E14: SANGO | F14: =COUNTIF(C:C,E14) -> 15
A15: =Products!A1427 -> ART00226 | B15: =Products!B1427 -> TOBIGO Bleo chocolate enrobé | C15: =IF(OR(ISNUMBER(SEARCH("SELHAM",B15)),ISNUMBER(SEARCH("LHAFLA",B15)),ISNUMBER(SEARCH("ZINE",B15)),ISNUMBER(SEARCH("tiyay",B15)),ISNUMBER(SEARCH("alouns",B15)),ISNUMBER(SEARCH("lmhrat",B15))),"The Al Itkane",IF(AND(ISNUMBER(SEARCH("CALIN",B15)),ISNUMBER(SEARCH("RP",B15)),NOT(ISNUMBER(SEARCH("VP",B15)))),"Calin RP",IF(AND(ISNUMBER(SEARCH("CALIN",B15)),ISNUMBER(SEARCH("VP",B15))),"Calin VP",IF(AND(ISNUMBER(SEARCH("MIO",B15)),OR(ISNUMBER(SEARCH("Vaisselle",B15)),ISNUMBER(SEARCH("vaisselle",B15)))),"Mio Liquid Vaisselle",IF(AND(ISNUMBER(SEARCH("MIO",B15)),ISNUMBER(SEARCH("Javel",B15))),"Mio Javel",IF(AND(ISNUMBER(SEARCH("MIO",B15)),ISNUMBER(SEARCH("Matic",B15))),"Mio Matic",IF(AND(ISNUMBER(SEARCH("MIO",B15)),OR(ISNUMBER(SEARCH("Détérgent",B15)),ISNUMBER(SEARCH("Poudre",B15)),ISNUMBER(SEARCH("Semi Auto",B15)),ISNUMBER(SEARCH("1KG",B15)),ISNUMBER(SEARCH("500G",B15)),ISNUMBER(SEARCH("10KG",B15)),ISNUMBER(SEARCH("1.5K",B15)),ISNUMBER(SEARCH("215G",B15)),ISNUMBER(SEARCH("350G",B15)),ISNUMBER(SEARCH("90G",B15)),ISNUMBER(SEARCH("Gold",B15)),ISNUMBER(SEARCH("Citron",B15)),ISNUMBER(SEARCH("Rose",B15)),ISNUMBER(SEARCH("Lessive",B15))),NOT(OR(ISNUMBER(SEARCH("Vaisselle",B15)),ISNUMBER(SEARCH("Javel",B15)),ISNUMBER(SEARCH("Matic",B15)),ISNUMBER(SEARCH("Nettoyant",B15)),ISNUMBER(SEARCH("Pâte",B15)),ISNUMBER(SEARCH("Lave",B15)),ISNUMBER(SEARCH("Détartrant",B15))))),"Mio main (1k+500gr)",IF(AND(ISNUMBER(SEARCH("PAPILLON",B15)),OR(ISNUMBER(SEARCH("Papier",B15)),ISNUMBER(SEARCH("Hygiénique",B15)),ISNUMBER(SEARCH("HYGIÉNIQUE",B15))),NOT(OR(ISNUMBER(SEARCH("Lingette",B15)),ISNUMBER(SEARCH("Mouchoir",B15))))),"Papillon Papier",IF(OR(ISNUMBER(SEARCH("TAJ AL SAHAR",B15)),ISNUMBER(SEARCH("TAJ BLADI",B15)),ISNUMBER(SEARCH("TAJ BELADI",B15)),ISNUMBER(SEARCH("Tilal Assahra",B15)),ISNUMBER(SEARCH("Jawharat Asahra",B15))),"TAJ SAHARA",IF(AND(OR(ISNUMBER(SEARCH("AL ITKANE",B15)),ISNUMBER(SEARCH("ALITKANE",B15)),ISNUMBER(SEARCH("PRESTO",B15))),NOT(OR(ISNUMBER(SEARCH("Thé",B15)),ISNUMBER(SEARCH("THE ",B15)),ISNUMBER(SEARCH("thé",B15)),ISNUMBER(SEARCH("SELHAM",B15)),ISNUMBER(SEARCH("LHAFLA",B15)),ISNUMBER(SEARCH("ZINE",B15)),ISNUMBER(SEARCH("tiyay",B15)),ISNUMBER(SEARCH("alouns",B15)),ISNUMBER(SEARCH("lmhrat",B15))))),"Al Itkrans + Presto",IF(OR(ISNUMBER(SEARCH("DALAA",B15)),ISNUMBER(SEARCH("CS-DALAA",B15)),ISNUMBER(SEARCH("DALINA",B15))),"Dalaa VP / Baqqal / RP",IF(OR(LEFT(UPPER(B15),4)="MIA ",LEFT(UPPER(B15),6)="CS-MIA"),"Mia",IF(OR(LEFT(UPPER(B15),5)="NOVA ",LEFT(UPPER(B15),7)="CS-NOVA"),"Nova",IF(OR(ISNUMBER(SEARCH("PRIMA ",B15)),ISNUMBER(SEARCH("CS-PRIMA",B15))),"Prima",IF(OR(ISNUMBER(SEARCH("Douceur",B15)),ISNUMBER(SEARCH("DOUCEUR",B15))),"Douceur",IF(OR(ISNUMBER(SEARCH("SANGO",B15)),ISNUMBER(SEARCH("CS-SANGO",B15))),"SANGO",IF(ISNUMBER(SEARCH("BLANDOUX",B15)),"Blandoux",IF(ISNUMBER(SEARCH("SHIWAMI",B15)),"Shiwame",IF(ISNUMBER(SEARCH("KELLOGG",B15)),"Kelloggs",IF(OR(ISNUMBER(SEARCH("TOBIGO",B15)),ISNUMBER(SEARCH("DWIST",B15))),"Tobigo",IF(OR(ISNUMBER(SEARCH("MARISOL",B15)),ISNUMBER(SEARCH("MARESOL",B15))),"Maresol",IF(OR(ISNUMBER(SEARCH("TAKIS",B15)),ISNUMBER(SEARCH("TAKYS",B15))),"TAKYS",IF(ISNUMBER(SEARCH("TAWIL",B15)),"Tawil",IF(ISNUMBER(SEARCH("FROMY",B15)),"Fromy","")))))))))))))))))))))))) -> Tobigo | E15: Blandoux | F15: =COUNTIF(C:C,E15) -> 1
A16: =Products!A1428 -> ART00227 | B16: =Products!B1428 -> TOBIGO Crousty Vanilla Cream | C16: =IF(OR(ISNUMBER(SEARCH("SELHAM",B16)),ISNUMBER(SEARCH("LHAFLA",B16)),ISNUMBER(SEARCH("ZINE",B16)),ISNUMBER(SEARCH("tiyay",B16)),ISNUMBER(SEARCH("alouns",B16)),ISNUMBER(SEARCH("lmhrat",B16))),"The Al Itkane",IF(AND(ISNUMBER(SEARCH("CALIN",B16)),ISNUMBER(SEARCH("RP",B16)),NOT(ISNUMBER(SEARCH("VP",B16)))),"Calin RP",IF(AND(ISNUMBER(SEARCH("CALIN",B16)),ISNUMBER(SEARCH("VP",B16))),"Calin VP",IF(AND(ISNUMBER(SEARCH("MIO",B16)),OR(ISNUMBER(SEARCH("Vaisselle",B16)),ISNUMBER(SEARCH("vaisselle",B16)))),"Mio Liquid Vaisselle",IF(AND(ISNUMBER(SEARCH("MIO",B16)),ISNUMBER(SEARCH("Javel",B16))),"Mio Javel",IF(AND(ISNUMBER(SEARCH("MIO",B16)),ISNUMBER(SEARCH("Matic",B16))),"Mio Matic",IF(AND(ISNUMBER(SEARCH("MIO",B16)),OR(ISNUMBER(SEARCH("Détérgent",B16)),ISNUMBER(SEARCH("Poudre",B16)),ISNUMBER(SEARCH("Semi Auto",B16)),ISNUMBER(SEARCH("1KG",B16)),ISNUMBER(SEARCH("500G",B16)),ISNUMBER(SEARCH("10KG",B16)),ISNUMBER(SEARCH("1.5K",B16)),ISNUMBER(SEARCH("215G",B16)),ISNUMBER(SEARCH("350G",B16)),ISNUMBER(SEARCH("90G",B16)),ISNUMBER(SEARCH("Gold",B16)),ISNUMBER(SEARCH("Citron",B16)),ISNUMBER(SEARCH("Rose",B16)),ISNUMBER(SEARCH("Lessive",B16))),NOT(OR(ISNUMBER(SEARCH("Vaisselle",B16)),ISNUMBER(SEARCH("Javel",B16)),ISNUMBER(SEARCH("Matic",B16)),ISNUMBER(SEARCH("Nettoyant",B16)),ISNUMBER(SEARCH("Pâte",B16)),ISNUMBER(SEARCH("Lave",B16)),ISNUMBER(SEARCH("Détartrant",B16))))),"Mio main (1k+500gr)",IF(AND(ISNUMBER(SEARCH("PAPILLON",B16)),OR(ISNUMBER(SEARCH("Papier",B16)),ISNUMBER(SEARCH("Hygiénique",B16)),ISNUMBER(SEARCH("HYGIÉNIQUE",B16))),NOT(OR(ISNUMBER(SEARCH("Lingette",B16)),ISNUMBER(SEARCH("Mouchoir",B16))))),"Papillon Papier",IF(OR(ISNUMBER(SEARCH("TAJ AL SAHAR",B16)),ISNUMBER(SEARCH("TAJ BLADI",B16)),ISNUMBER(SEARCH("TAJ BELADI",B16)),ISNUMBER(SEARCH("Tilal Assahra",B16)),ISNUMBER(SEARCH("Jawharat Asahra",B16))),"TAJ SAHARA",IF(AND(OR(ISNUMBER(SEARCH("AL ITKANE",B16)),ISNUMBER(SEARCH("ALITKANE",B16)),ISNUMBER(SEARCH("PRESTO",B16))),NOT(OR(ISNUMBER(SEARCH("Thé",B16)),ISNUMBER(SEARCH("THE ",B16)),ISNUMBER(SEARCH("thé",B16)),ISNUMBER(SEARCH("SELHAM",B16)),ISNUMBER(SEARCH("LHAFLA",B16)),ISNUMBER(SEARCH("ZINE",B16)),ISNUMBER(SEARCH("tiyay",B16)),ISNUMBER(SEARCH("alouns",B16)),ISNUMBER(SEARCH("lmhrat",B16))))),"Al Itkrans + Presto",IF(OR(ISNUMBER(SEARCH("DALAA",B16)),ISNUMBER(SEARCH("CS-DALAA",B16)),ISNUMBER(SEARCH("DALINA",B16))),"Dalaa VP / Baqqal / RP",IF(OR(LEFT(UPPER(B16),4)="MIA ",LEFT(UPPER(B16),6)="CS-MIA"),"Mia",IF(OR(LEFT(UPPER(B16),5)="NOVA ",LEFT(UPPER(B16),7)="CS-NOVA"),"Nova",IF(OR(ISNUMBER(SEARCH("PRIMA ",B16)),ISNUMBER(SEARCH("CS-PRIMA",B16))),"Prima",IF(OR(ISNUMBER(SEARCH("Douceur",B16)),ISNUMBER(SEARCH("DOUCEUR",B16))),"Douceur",IF(OR(ISNUMBER(SEARCH("SANGO",B16)),ISNUMBER(SEARCH("CS-SANGO",B16))),"SANGO",IF(ISNUMBER(SEARCH("BLANDOUX",B16)),"Blandoux",IF(ISNUMBER(SEARCH("SHIWAMI",B16)),"Shiwame",IF(ISNUMBER(SEARCH("KELLOGG",B16)),"Kelloggs",IF(OR(ISNUMBER(SEARCH("TOBIGO",B16)),ISNUMBER(SEARCH("DWIST",B16))),"Tobigo",IF(OR(ISNUMBER(SEARCH("MARISOL",B16)),ISNUMBER(SEARCH("MARESOL",B16))),"Maresol",IF(OR(ISNUMBER(SEARCH("TAKIS",B16)),ISNUMBER(SEARCH("TAKYS",B16))),"TAKYS",IF(ISNUMBER(SEARCH("TAWIL",B16)),"Tawil",IF(ISNUMBER(SEARCH("FROMY",B16)),"Fromy","")))))))))))))))))))))))) -> Tobigo | E16: Shiwame | F16: =COUNTIF(C:C,E16) -> 8
A17: =Products!A1429 -> ART00228 | B17: =Products!B1429 -> TOBIGO Trio Choco & Coco | C17: =IF(OR(ISNUMBER(SEARCH("SELHAM",B17)),ISNUMBER(SEARCH("LHAFLA",B17)),ISNUMBER(SEARCH("ZINE",B17)),ISNUMBER(SEARCH("tiyay",B17)),ISNUMBER(SEARCH("alouns",B17)),ISNUMBER(SEARCH("lmhrat",B17))),"The Al Itkane",IF(AND(ISNUMBER(SEARCH("CALIN",B17)),ISNUMBER(SEARCH("RP",B17)),NOT(ISNUMBER(SEARCH("VP",B17)))),"Calin RP",IF(AND(ISNUMBER(SEARCH("CALIN",B17)),ISNUMBER(SEARCH("VP",B17))),"Calin VP",IF(AND(ISNUMBER(SEARCH("MIO",B17)),OR(ISNUMBER(SEARCH("Vaisselle",B17)),ISNUMBER(SEARCH("vaisselle",B17)))),"Mio Liquid Vaisselle",IF(AND(ISNUMBER(SEARCH("MIO",B17)),ISNUMBER(SEARCH("Javel",B17))),"Mio Javel",IF(AND(ISNUMBER(SEARCH("MIO",B17)),ISNUMBER(SEARCH("Matic",B17))),"Mio Matic",IF(AND(ISNUMBER(SEARCH("MIO",B17)),OR(ISNUMBER(SEARCH("Détérgent",B17)),ISNUMBER(SEARCH("Poudre",B17)),ISNUMBER(SEARCH("Semi Auto",B17)),ISNUMBER(SEARCH("1KG",B17)),ISNUMBER(SEARCH("500G",B17)),ISNUMBER(SEARCH("10KG",B17)),ISNUMBER(SEARCH("1.5K",B17)),ISNUMBER(SEARCH("215G",B17)),ISNUMBER(SEARCH("350G",B17)),ISNUMBER(SEARCH("90G",B17)),ISNUMBER(SEARCH("Gold",B17)),ISNUMBER(SEARCH("Citron",B17)),ISNUMBER(SEARCH("Rose",B17)),ISNUMBER(SEARCH("Lessive",B17))),NOT(OR(ISNUMBER(SEARCH("Vaisselle",B17)),ISNUMBER(SEARCH("Javel",B17)),ISNUMBER(SEARCH("Matic",B17)),ISNUMBER(SEARCH("Nettoyant",B17)),ISNUMBER(SEARCH("Pâte",B17)),ISNUMBER(SEARCH("Lave",B17)),ISNUMBER(SEARCH("Détartrant",B17))))),"Mio main (1k+500gr)",IF(AND(ISNUMBER(SEARCH("PAPILLON",B17)),OR(ISNUMBER(SEARCH("Papier",B17)),ISNUMBER(SEARCH("Hygiénique",B17)),ISNUMBER(SEARCH("HYGIÉNIQUE",B17))),NOT(OR(ISNUMBER(SEARCH("Lingette",B17)),ISNUMBER(SEARCH("Mouchoir",B17))))),"Papillon Papier",IF(OR(ISNUMBER(SEARCH("TAJ AL SAHAR",B17)),ISNUMBER(SEARCH("TAJ BLADI",B17)),ISNUMBER(SEARCH("TAJ BELADI",B17)),ISNUMBER(SEARCH("Tilal Assahra",B17)),ISNUMBER(SEARCH("Jawharat Asahra",B17))),"TAJ SAHARA",IF(AND(OR(ISNUMBER(SEARCH("AL ITKANE",B17)),ISNUMBER(SEARCH("ALITKANE",B17)),ISNUMBER(SEARCH("PRESTO",B17))),NOT(OR(ISNUMBER(SEARCH("Thé",B17)),ISNUMBER(SEARCH("THE ",B17)),ISNUMBER(SEARCH("thé",B17)),ISNUMBER(SEARCH("SELHAM",B17)),ISNUMBER(SEARCH("LHAFLA",B17)),ISNUMBER(SEARCH("ZINE",B17)),ISNUMBER(SEARCH("tiyay",B17)),ISNUMBER(SEARCH("alouns",B17)),ISNUMBER(SEARCH("lmhrat",B17))))),"Al Itkrans + Presto",IF(OR(ISNUMBER(SEARCH("DALAA",B17)),ISNUMBER(SEARCH("CS-DALAA",B17)),ISNUMBER(SEARCH("DALINA",B17))),"Dalaa VP / Baqqal / RP",IF(OR(LEFT(UPPER(B17),4)="MIA ",LEFT(UPPER(B17),6)="CS-MIA"),"Mia",IF(OR(LEFT(UPPER(B17),5)="NOVA ",LEFT(UPPER(B17),7)="CS-NOVA"),"Nova",IF(OR(ISNUMBER(SEARCH("PRIMA ",B17)),ISNUMBER(SEARCH("CS-PRIMA",B17))),"Prima",IF(OR(ISNUMBER(SEARCH("Douceur",B17)),ISNUMBER(SEARCH("DOUCEUR",B17))),"Douceur",IF(OR(ISNUMBER(SEARCH("SANGO",B17)),ISNUMBER(SEARCH("CS-SANGO",B17))),"SANGO",IF(ISNUMBER(SEARCH("BLANDOUX",B17)),"Blandoux",IF(ISNUMBER(SEARCH("SHIWAMI",B17)),"Shiwame",IF(ISNUMBER(SEARCH("KELLOGG",B17)),"Kelloggs",IF(OR(ISNUMBER(SEARCH("TOBIGO",B17)),ISNUMBER(SEARCH("DWIST",B17))),"Tobigo",IF(OR(ISNUMBER(SEARCH("MARISOL",B17)),ISNUMBER(SEARCH("MARESOL",B17))),"Maresol",IF(OR(ISNUMBER(SEARCH("TAKIS",B17)),ISNUMBER(SEARCH("TAKYS",B17))),"TAKYS",IF(ISNUMBER(SEARCH("TAWIL",B17)),"Tawil",IF(ISNUMBER(SEARCH("FROMY",B17)),"Fromy","")))))))))))))))))))))))) -> Tobigo | E17: Kelloggs | F17: =COUNTIF(C:C,E17) -> 7
A18: =Products!A1430 -> ART00229 | B18: =Products!B1430 -> TOBIGO Cookies | C18: =IF(OR(ISNUMBER(SEARCH("SELHAM",B18)),ISNUMBER(SEARCH("LHAFLA",B18)),ISNUMBER(SEARCH("ZINE",B18)),ISNUMBER(SEARCH("tiyay",B18)),ISNUMBER(SEARCH("alouns",B18)),ISNUMBER(SEARCH("lmhrat",B18))),"The Al Itkane",IF(AND(ISNUMBER(SEARCH("CALIN",B18)),ISNUMBER(SEARCH("RP",B18)),NOT(ISNUMBER(SEARCH("VP",B18)))),"Calin RP",IF(AND(ISNUMBER(SEARCH("CALIN",B18)),ISNUMBER(SEARCH("VP",B18))),"Calin VP",IF(AND(ISNUMBER(SEARCH("MIO",B18)),OR(ISNUMBER(SEARCH("Vaisselle",B18)),ISNUMBER(SEARCH("vaisselle",B18)))),"Mio Liquid Vaisselle",IF(AND(ISNUMBER(SEARCH("MIO",B18)),ISNUMBER(SEARCH("Javel",B18))),"Mio Javel",IF(AND(ISNUMBER(SEARCH("MIO",B18)),ISNUMBER(SEARCH("Matic",B18))),"Mio Matic",IF(AND(ISNUMBER(SEARCH("MIO",B18)),OR(ISNUMBER(SEARCH("Détérgent",B18)),ISNUMBER(SEARCH("Poudre",B18)),ISNUMBER(SEARCH("Semi Auto",B18)),ISNUMBER(SEARCH("1KG",B18)),ISNUMBER(SEARCH("500G",B18)),ISNUMBER(SEARCH("10KG",B18)),ISNUMBER(SEARCH("1.5K",B18)),ISNUMBER(SEARCH("215G",B18)),ISNUMBER(SEARCH("350G",B18)),ISNUMBER(SEARCH("90G",B18)),ISNUMBER(SEARCH("Gold",B18)),ISNUMBER(SEARCH("Citron",B18)),ISNUMBER(SEARCH("Rose",B18)),ISNUMBER(SEARCH("Lessive",B18))),NOT(OR(ISNUMBER(SEARCH("Vaisselle",B18)),ISNUMBER(SEARCH("Javel",B18)),ISNUMBER(SEARCH("Matic",B18)),ISNUMBER(SEARCH("Nettoyant",B18)),ISNUMBER(SEARCH("Pâte",B18)),ISNUMBER(SEARCH("Lave",B18)),ISNUMBER(SEARCH("Détartrant",B18))))),"Mio main (1k+500gr)",IF(AND(ISNUMBER(SEARCH("PAPILLON",B18)),OR(ISNUMBER(SEARCH("Papier",B18)),ISNUMBER(SEARCH("Hygiénique",B18)),ISNUMBER(SEARCH("HYGIÉNIQUE",B18))),NOT(OR(ISNUMBER(SEARCH("Lingette",B18)),ISNUMBER(SEARCH("Mouchoir",B18))))),"Papillon Papier",IF(OR(ISNUMBER(SEARCH("TAJ AL SAHAR",B18)),ISNUMBER(SEARCH("TAJ BLADI",B18)),ISNUMBER(SEARCH("TAJ BELADI",B18)),ISNUMBER(SEARCH("Tilal Assahra",B18)),ISNUMBER(SEARCH("Jawharat Asahra",B18))),"TAJ SAHARA",IF(AND(OR(ISNUMBER(SEARCH("AL ITKANE",B18)),ISNUMBER(SEARCH("ALITKANE",B18)),ISNUMBER(SEARCH("PRESTO",B18))),NOT(OR(ISNUMBER(SEARCH("Thé",B18)),ISNUMBER(SEARCH("THE ",B18)),ISNUMBER(SEARCH("thé",B18)),ISNUMBER(SEARCH("SELHAM",B18)),ISNUMBER(SEARCH("LHAFLA",B18)),ISNUMBER(SEARCH("ZINE",B18)),ISNUMBER(SEARCH("tiyay",B18)),ISNUMBER(SEARCH("alouns",B18)),ISNUMBER(SEARCH("lmhrat",B18))))),"Al Itkrans + Presto",IF(OR(ISNUMBER(SEARCH("DALAA",B18)),ISNUMBER(SEARCH("CS-DALAA",B18)),ISNUMBER(SEARCH("DALINA",B18))),"Dalaa VP / Baqqal / RP",IF(OR(LEFT(UPPER(B18),4)="MIA ",LEFT(UPPER(B18),6)="CS-MIA"),"Mia",IF(OR(LEFT(UPPER(B18),5)="NOVA ",LEFT(UPPER(B18),7)="CS-NOVA"),"Nova",IF(OR(ISNUMBER(SEARCH("PRIMA ",B18)),ISNUMBER(SEARCH("CS-PRIMA",B18))),"Prima",IF(OR(ISNUMBER(SEARCH("Douceur",B18)),ISNUMBER(SEARCH("DOUCEUR",B18))),"Douceur",IF(OR(ISNUMBER(SEARCH("SANGO",B18)),ISNUMBER(SEARCH("CS-SANGO",B18))),"SANGO",IF(ISNUMBER(SEARCH("BLANDOUX",B18)),"Blandoux",IF(ISNUMBER(SEARCH("SHIWAMI",B18)),"Shiwame",IF(ISNUMBER(SEARCH("KELLOGG",B18)),"Kelloggs",IF(OR(ISNUMBER(SEARCH("TOBIGO",B18)),ISNUMBER(SEARCH("DWIST",B18))),"Tobigo",IF(OR(ISNUMBER(SEARCH("MARISOL",B18)),ISNUMBER(SEARCH("MARESOL",B18))),"Maresol",IF(OR(ISNUMBER(SEARCH("TAKIS",B18)),ISNUMBER(SEARCH("TAKYS",B18))),"TAKYS",IF(ISNUMBER(SEARCH("TAWIL",B18)),"Tawil",IF(ISNUMBER(SEARCH("FROMY",B18)),"Fromy","")))))))))))))))))))))))) -> Tobigo | E18: Al Itkrans + Presto | F18: =COUNTIF(C:C,E18) -> 91
